Workbook
Name Holidays: [1]Assumptions!$R$3:$R$36
Name Sales_BU: [2]Sales!$B$79:$B$90
Name Sales_Forecast: [2]Sales!$B$79:$O$90
Name Sales_Month: [2]Sales!$B$79:$O$79
Name valuevx: 42.314159

Sheet Notes
A1: NOTES
A3: Date | B3: Initials | C3: Details
A5: 44070 | B5: ALS | C5: Setup template
A6: 44070 | B6: ALS | C6: Completed first draft costs, investments + cap table
A7: 44071 | B7: ALS | C7: Created Roadmap + first draft ROI analysis + Rev Forecast

Sheet Assumptions
A1: Assumption
A2: The plan is prepared for the following audience: Angel Investors, Seed Round Investment Firms
A3: VReeMind will be a fully remote operation
A4: Each new hire will be provided a $5000 work-from-home package to supplement office equipment costs

Sheet Roadmap
C1: CRITICAL PATHWAY | E1: Gate 1 | K1: Gate 2 | Q1: GATE 3 | AC1: GATE 4 | AO1: GATE 5 | BA1: GATE 6
E2: Month 1 | F2: Month 2 | G2: Month 3 | H2: Month 4 | I2: Month 5 | J2: Month 6 | K2: Month 7 | L2: Month 8 | M2: Month 9 | N2: Month 10 | O2: Month 11 | P2: Month 12 | Q2: Month 13 | R2: Month 14 | S2: Month 15 | T2: Month 16 | U2: Month 17 | V2: Month 18 | W2: Month 19 | X2: Month 20 | Y2: Month 21 | Z2: Month 22 | AA2: Month 23 | AB2: Month 24 | AC2: Month 25 | AD2: Month 26 | AE2: Month 27 | AF2: Month 28 | AG2: Month 29 | AH2: Month 30 | AI2: Month 31 | AJ2: Month 32 | AK2: Month 33 | AL2: Month 34 | AM2: Month 35 | AN2: Month 36 | AO2: Month 37 | AP2: Month 38 | AQ2: Month 39 | AR2: Month 40 | AS2: Month 41 | AT2: Month 42 | AU2: Month 43 | AV2: Month 44 | AW2: Month 45 | AX2: Month 46 | AY2: Month 47 | AZ2: Month 48 | BA2: Month 49 | BB2: Month 50 | BC2: Month 51 | BD2: Month 52 | BE2: Month 53 | BF2: Month 54 | BG2: Month 55 | BH2: Month 56 | BI2: Month 57 | BJ2: Month 58 | BK2: Month 59 | BL2: Month 60
C4: CORPORATE & TAX | E4: Incorporate Co. | Q4: Annual Return | AC4: Annual Return | AN4: Form UK/EU Co. | AO4: Annual Return
C6: MARKETS | E6: US / Consumer | Q6: US / Health Service | W6: US / Corporate | AO6: Europe / Consumer | AU6: Europe / Health Services | BA6: Europe / Corporate
C8: INVESTMENT | H8: Seed | Q8: Series A VC Funding | AC8: Series B VC Funding | AO8: Series C VC Funding | BA8: Series D VC Funding | BG8: EXIT
C10: ACCOUNTING | P10: End of Year Accounts | AB10: End of Year Accounts | AN10: End of Year Accounts | AZ10: End of Year Accounts | BD10: Exit Accounts Preparation
C12: IP | G12: Patent(s) Drafted | H12: US Patents Pending | L12: IP Valuation | T12: PCT Patents Pending | Z12: US Patents Granted | AL12: PCT Patents Granted
C14: TECHNOLOGY | G14: POC | J14: Mob v1.0 | P14: Mob v2.0 | V14: Mob v2.5 | AB14: Mob v3.0 | AH14: Mob v3.5 | AN14: VR v1.0 | AQ14: Mob v4.0 | AT14: VR v1.5 | AW14: Mob v4.5 | AZ14: VR v2.0 | BC14: VR v2.5 | BF14: VR v3.0
C16: TRACTION (Paid Subscribers) | K16: ='Rev Forecast'!L15 -> 50000 | Q16: ='Rev Forecast'!R15 -> 100000 | W16: ='Rev Forecast'!X15 -> 250000 | AC16: ='Rev Forecast'!AD15 -> 500000 | AI16: ='Rev Forecast'!AJ15 -> 1000000 | AO16: ='Rev Forecast'!AP15 -> 2000000 | AR16: ='Rev Forecast'!AS15 -> 2500000 | AU16: ='Rev Forecast'!AV15 -> 3000000 | AX16: ='Rev Forecast'!AY15 -> 3500000 | BA16: ='Rev Forecast'!BB15 -> 4500000 | BD16: ='Rev Forecast'!BE15 -> 5000000 | BG16: ='Rev Forecast'!BH15 -> 7000000

Sheet Investment & Cash
E1: 2021 | Q1: =E1+1 -> 2022 | AC1: =Q1+1 -> 2023 | AO1: =AC1+1 -> 2024 | BA1: =AO1+1 -> 2025 | BN1: TOTAL | BP1: =E1 -> 2021 | BT1: =BP1+1 -> 2022 | BX1: =BT1+1 -> 2023 | CB1: =BX1+1 -> 2024 | CF1: =CB1+1 -> 2025 | CL1: =BA1+1 -> 2026 | CN1: =CL1+1 -> 2027 | CP1: =CN1+1 -> 2028 | CR1: =CP1+1 -> 2029 | CT1: =CR1+1 -> 2030 | CV1: =CT1+1 -> 2031 | CX1: =CV1+1 -> 2032 | CZ1: =CX1+1 -> 2033 | DB1: =CZ1+1 -> 2034 | DD1: =DB1+1 -> 2035 | DF1: =DD1+1 -> 2036 | DH1: =DF1+1 -> 2037
E2: Month 1 | F2: Month 2 | G2: Month 3 | H2: Month 4 | I2: Month 5 | J2: Month 6 | K2: Month 7 | L2: Month 8 | M2: Month 9 | N2: Month 10 | O2: Month 11 | P2: Month 12 | Q2: Month 13 | R2: Month 14 | S2: Month 15 | T2: Month 16 | U2: Month 17 | V2: Month 18 | W2: Month 19 | X2: Month 20 | Y2: Month 21 | Z2: Month 22 | AA2: Month 23 | AB2: Month 24 | AC2: Month 25 | AD2: Month 26 | AE2: Month 27 | AF2: Month 28 | AG2: Month 29 | AH2: Month 30 | AI2: Month 31 | AJ2: Month 32 | AK2: Month 33 | AL2: Month 34 | AM2: Month 35 | AN2: Month 36 | AO2: Month 37 | AP2: Month 38 | AQ2: Month 39 | AR2: Month 40 | AS2: Month 41 | AT2: Month 42 | AU2: Month 43 | AV2: Month 44 | AW2: Month 45 | AX2: Month 46 | AY2: Month 47 | AZ2: Month 48 | BA2: Month 49 | BB2: Month 50 | BC2: Month 51 | BD2: Month 52 | BE2: Month 53 | BF2: Month 54 | BG2: Month 55 | BH2: Month 56 | BI2: Month 57 | BJ2: Month 58 | BK2: Month 59 | BL2: Month 60 | BN2: x | BP2: Q1 | BQ2: Q2 | BR2: Q3 | BS2: Q4 | BT2: Q1 | BU2: Q2 | BV2: Q3 | BW2: Q4 | BX2: Q1 | BY2: Q2 | BZ2: Q3 | CA2: Q4 | CB2: Q1 | CC2: Q2 | CD2: Q3 | CE2: Q4 | CF2: Q1 | CG2: Q2 | CH2: Q3 | CI2: Q4
BN3: x | BP3: =SUM(E3:G3) -> 0 | BQ3: =SUM(H3:J3) -> 0 | BR3: =SUM(K3:M3) -> 0 | BS3: =SUM(N3:P3) -> 0 | BT3: =SUM(Q3:S3) -> 0 | BU3: =SUM(T3:V3) -> 0 | BV3: =SUM(W3:Y3) -> 0 | BW3: =SUM(Z3:AB3) -> 0 | BX3: =SUM(AC3:AE3) -> 0 | BY3: =SUM(AF3:AH3) -> 0 | BZ3: =SUM(AI3:AK3) -> 0 | CA3: =SUM(AL3:AN3) -> 0 | CB3: =SUM(AO3:AQ3) -> 0 | CC3: =SUM(AR3:AT3) -> 0 | CD3: =SUM(AU3:AW3) -> 0 | CE3: =SUM(AX3:AZ3) -> 0 | CF3: =SUM(BA3:BC3) -> 0 | CG3: =SUM(BD3:BF3) -> 0 | CH3: =SUM(BG3:BI3) -> 0 | CI3: =SUM(BJ3:BL3) -> 0 | CK3: 0.05 | CL3: =SUM(CF3:CI3)*(-1-$CK3) -> 0 | CM3: =CK3 -> 0.05 | CN3: =SUM(CL3)*(-1-$CM3) -> 0 | CO3: =CM3 -> 0.05 | CP3: =SUM(CN3)*(-1-$CM3) -> 0 | CQ3: =CO3 -> 0.05 | CR3: =SUM(CP3)*(-1-$CM3) -> 0 | CS3: =CQ3 -> 0.05 | CT3: =SUM(CR3)*(-1-$CM3) -> 0 | CU3: =CS3 -> 0.05 | CV3: =SUM(CT3)*(-1-$CM3) -> 0 | CW3: =CU3 -> 0.05 | CX3: =SUM(CV3)*(-1-$CM3) -> 0 | CY3: =CW3 -> 0.05 | CZ3: =SUM(CX3)*(-1-$CM3) -> 0 | DA3: =CY3 -> 0.05 | DB3: =SUM(CZ3)*(-1-$CM3) -> 0 | DC3: =DA3 -> 0.05 | DD3: =SUM(DB3)*(-1-$CM3) -> 0 | DE3: =DC3 -> 0.05 | DF3: =SUM(DD3)*(-1-$CM3) -> 0 | DG3: =DE3 -> 0.05 | DH3: =SUM(DF3)*(-1-$CM3) -> 0
D4: TOTAL | E4: =SUM(E7,E17,E26) -> 50000 | F4: =SUM(F7,F17,F26) -> 0 | G4: =SUM(G7,G17,G26) -> 0 | H4: =SUM(H7,H17,H26) -> 350000 | I4: =SUM(I7,I17,I26) -> 0 | J4: =SUM(J7,J17,J26) -> 0 | K4: =SUM(K7,K17,K26) -> 0 | L4: =SUM(L7,L17,L26) -> 0 | ... BL4: =SUM(BL7,BL17,BL26) -> 0 | BN4: x
BN5: x
BN6: x
B7: Investment | D7: Sub Total | E7: =SUM(E9:E13) -> 50000 | F7: =SUM(F9:F13) -> 0 | G7: =SUM(G9:G13) -> 0 | H7: =SUM(H9:H13) -> 350000 | I7: =SUM(I9:I13) -> 0 | J7: =SUM(J9:J13) -> 0 | K7: =SUM(K9:K13) -> 0 | L7: =SUM(L9:L13) -> 0 | ... BL7: =SUM(BL9:BL13) -> 0 | BN7: x
BN8: x
B9: Pre-seed | C9: ='Cap Table'!B36 -> 50000 | D9: Month 1 | E9: =IF(E$2=$D9,$C9,0) -> 50000 | F9: =IF(F$2=$D9,$C9,0) -> 0 | G9: =IF(G$2=$D9,$C9,0) -> 0 | H9: =IF(H$2=$D9,$C9,0) -> 0 | I9: =IF(I$2=$D9,$C9,0) -> 0 | J9: =IF(J$2=$D9,$C9,0) -> 0 | K9: =IF(K$2=$D9,$C9,0) -> 0 | L9: =IF(L$2=$D9,$C9,0) -> 0 | ... BL9: =IF(BL$2=$D9,$C9,0) -> 0 | BN9: x
B10: Seed | C10: ='Cap Table'!F36 -> 350000 | D10: Month 4 | E10: =IF(E$2=$D10,$C10,0) -> 0 | F10: =IF(F$2=$D10,$C10,0) -> 0 | G10: =IF(G$2=$D10,$C10,0) -> 0 | H10: =IF(H$2=$D10,$C10,0) -> 350000 | I10: =IF(I$2=$D10,$C10,0) -> 0 | J10: =IF(J$2=$D10,$C10,0) -> 0 | K10: =IF(K$2=$D10,$C10,0) -> 0 | L10: =IF(L$2=$D10,$C10,0) -> 0 | ... BL10: =IF(BL$2=$D10,$C10,0) -> 0 | BN10: x
B11: A Series | C11: ='Cap Table'!J36 -> 1000000 | D11: Month 13 | E11: =IF(E$2=$D11,$C11,0) -> 0 | F11: =IF(F$2=$D11,$C11,0) -> 0 | G11: =IF(G$2=$D11,$C11,0) -> 0 | H11: =IF(H$2=$D11,$C11,0) -> 0 | I11: =IF(I$2=$D11,$C11,0) -> 0 | J11: =IF(J$2=$D11,$C11,0) -> 0 | K11: =IF(K$2=$D11,$C11,0) -> 0 | L11: =IF(L$2=$D11,$C11,0) -> 0 | ... BL11: =IF(BL$2=$D11,$C11,0) -> 0 | BN11: x
B12: B Series | C12: ='Cap Table'!N36 -> 3500000 | D12: Month 25 | E12: =IF(E$2=$D12,$C12,0) -> 0 | F12: =IF(F$2=$D12,$C12,0) -> 0 | G12: =IF(G$2=$D12,$C12,0) -> 0 | H12: =IF(H$2=$D12,$C12,0) -> 0 | I12: =IF(I$2=$D12,$C12,0) -> 0 | J12: =IF(J$2=$D12,$C12,0) -> 0 | K12: =IF(K$2=$D12,$C12,0) -> 0 | L12: =IF(L$2=$D12,$C12,0) -> 0 | ... BL12: =IF(BL$2=$D12,$C12,0) -> 0 | BN12: x
B13: C Series | C13: ='Cap Table'!R36 -> 5000000 | D13: Month 37 | E13: =IF(E$2=$D13,$C13,0) -> 0 | F13: =IF(F$2=$D13,$C13,0) -> 0 | G13: =IF(G$2=$D13,$C13,0) -> 0 | H13: =IF(H$2=$D13,$C13,0) -> 0 | I13: =IF(I$2=$D13,$C13,0) -> 0 | J13: =IF(J$2=$D13,$C13,0) -> 0 | K13: =IF(K$2=$D13,$C13,0) -> 0 | L13: =IF(L$2=$D13,$C13,0) -> 0 | ... BL13: =IF(BL$2=$D13,$C13,0) -> 0 | BN13: x
B14: D Series | C14: ='Cap Table'!V36 -> 10000000 | D14: Month 49 | E14: =IF(E$2=$D14,$C14,0) -> 0 | F14: =IF(F$2=$D14,$C14,0) -> 0 | G14: =IF(G$2=$D14,$C14,0) -> 0 | H14: =IF(H$2=$D14,$C14,0) -> 0 | I14: =IF(I$2=$D14,$C14,0) -> 0 | J14: =IF(J$2=$D14,$C14,0) -> 0 | K14: =IF(K$2=$D14,$C14,0) -> 0 | L14: =IF(L$2=$D14,$C14,0) -> 0 | ... BL14: =IF(BL$2=$D14,$C14,0) -> 0 | BN14: x
BN16: x
B17: Grants | D17: Sub Total | E17: =SUM(E19:E23) -> 0 | F17: =SUM(F19:F23) -> 0 | G17: =SUM(G19:G23) -> 0 | H17: =SUM(H19:H23) -> 0 | I17: =SUM(I19:I23) -> 0 | J17: =SUM(J19:J23) -> 0 | K17: =SUM(K19:K23) -> 0 | L17: =SUM(L19:L23) -> 0 | ... BL17: =SUM(BL19:BL23) -> 0 | BN17: x
BN18: x
B19: - | E19: 0 | F19: 0 | G19: 0 | H19: 0 | I19: 0 | J19: 0 | K19: 0 | L19: 0 | M19: 0 | N19: 0 | O19: 0 | P19: 0 | Q19: 0 | R19: 0 | S19: 0 | T19: 0 | U19: 0 | V19: 0 | W19: 0 | X19: 0 | Y19: 0 | Z19: 0 | AA19: 0 | AB19: 0 | AC19: 0 | AD19: 0 | AE19: 0 | AF19: 0 | AG19: 0 | AH19: 0 | AI19: 0 | AJ19: 0 | AK19: 0 | AL19: 0 | AM19: 0 | AN19: 0 | AO19: 0 | AP19: 0 | AQ19: 0 | AR19: 0 | AS19: 0 | AT19: 0 | AU19: 0 | AV19: 0 | AW19: 0 | AX19: 0 | AY19: 0 | AZ19: 0 | BA19: 0 | BB19: 0 | BC19: 0 | BD19: 0 | BE19: 0 | BF19: 0 | BG19: 0 | BH19: 0 | BI19: 0 | BJ19: 0 | BK19: 0 | BL19: 0 | BN19: x
B20: - | E20: 0 | F20: 0 | G20: 0 | H20: 0 | I20: 0 | J20: 0 | K20: 0 | L20: 0 | M20: 0 | N20: 0 | O20: 0 | P20: 0 | Q20: 0 | R20: 0 | S20: 0 | T20: 0 | U20: 0 | V20: 0 | W20: 0 | X20: 0 | Y20: 0 | Z20: 0 | AA20: 0 | AB20: 0 | AC20: 0 | AD20: 0 | AE20: 0 | AF20: 0 | AG20: 0 | AH20: 0 | AI20: 0 | AJ20: 0 | AK20: 0 | AL20: 0 | AM20: 0 | AN20: 0 | AO20: 0 | AP20: 0 | AQ20: 0 | AR20: 0 | AS20: 0 | AT20: 0 | AU20: 0 | AV20: 0 | AW20: 0 | AX20: 0 | AY20: 0 | AZ20: 0 | BA20: 0 | BB20: 0 | BC20: 0 | BD20: 0 | BE20: 0 | BF20: 0 | BG20: 0 | BH20: 0 | BI20: 0 | BJ20: 0 | BK20: 0 | BL20: 0 | BN20: x
B21: - | E21: 0 | F21: 0 | G21: 0 | H21: 0 | I21: 0 | J21: 0 | K21: 0 | L21: 0 | M21: 0 | N21: 0 | O21: 0 | P21: 0 | Q21: 0 | R21: 0 | S21: 0 | T21: 0 | U21: 0 | V21: 0 | W21: 0 | X21: 0 | Y21: 0 | Z21: 0 | AA21: 0 | AB21: 0 | AC21: 0 | AD21: 0 | AE21: 0 | AF21: 0 | AG21: 0 | AH21: 0 | AI21: 0 | AJ21: 0 | AK21: 0 | AL21: 0 | AM21: 0 | AN21: 0 | AO21: 0 | AP21: 0 | AQ21: 0 | AR21: 0 | AS21: 0 | AT21: 0 | AU21: 0 | AV21: 0 | AW21: 0 | AX21: 0 | AY21: 0 | AZ21: 0 | BA21: 0 | BB21: 0 | BC21: 0 | BD21: 0 | BE21: 0 | BF21: 0 | BG21: 0 | BH21: 0 | BI21: 0 | BJ21: 0 | BK21: 0 | BL21: 0 | BN21: x
B22: - | E22: 0 | F22: 0 | G22: 0 | H22: 0 | I22: 0 | J22: 0 | K22: 0 | L22: 0 | M22: 0 | N22: 0 | O22: 0 | P22: 0 | Q22: 0 | R22: 0 | S22: 0 | T22: 0 | U22: 0 | V22: 0 | W22: 0 | X22: 0 | Y22: 0 | Z22: 0 | AA22: 0 | AB22: 0 | AC22: 0 | AD22: 0 | AE22: 0 | AF22: 0 | AG22: 0 | AH22: 0 | AI22: 0 | AJ22: 0 | AK22: 0 | AL22: 0 | AM22: 0 | AN22: 0 | AO22: 0 | AP22: 0 | AQ22: 0 | AR22: 0 | AS22: 0 | AT22: 0 | AU22: 0 | AV22: 0 | AW22: 0 | AX22: 0 | AY22: 0 | AZ22: 0 | BA22: 0 | BB22: 0 | BC22: 0 | BD22: 0 | BE22: 0 | BF22: 0 | BG22: 0 | BH22: 0 | BI22: 0 | BJ22: 0 | BK22: 0 | BL22: 0 | BN22: x
B23: - | E23: 0 | F23: 0 | G23: 0 | H23: 0 | I23: 0 | J23: 0 | K23: 0 | L23: 0 | M23: 0 | N23: 0 | O23: 0 | P23: 0 | Q23: 0 | R23: 0 | S23: 0 | T23: 0 | U23: 0 | V23: 0 | W23: 0 | X23: 0 | Y23: 0 | Z23: 0 | AA23: 0 | AB23: 0 | AC23: 0 | AD23: 0 | AE23: 0 | AF23: 0 | AG23: 0 | AH23: 0 | AI23: 0 | AJ23: 0 | AK23: 0 | AL23: 0 | AM23: 0 | AN23: 0 | AO23: 0 | AP23: 0 | AQ23: 0 | AR23: 0 | AS23: 0 | AT23: 0 | AU23: 0 | AV23: 0 | AW23: 0 | AX23: 0 | AY23: 0 | AZ23: 0 | BA23: 0 | BB23: 0 | BC23: 0 | BD23: 0 | BE23: 0 | BF23: 0 | BG23: 0 | BH23: 0 | BI23: 0 | BJ23: 0 | BK23: 0 | BL23: 0 | BN23: x
BN24: x
BN25: x
B26: ICO/ STO | D26: Sub Total | E26: =SUM(E28:E32) -> 0 | F26: =SUM(F28:F32) -> 0 | G26: =SUM(G28:G32) -> 0 | H26: =SUM(H28:H32) -> 0 | I26: =SUM(I28:I32) -> 0 | J26: =SUM(J28:J32) -> 0 | K26: =SUM(K28:K32) -> 0 | L26: =SUM(L28:L32) -> 0 | ... BL26: =SUM(BL28:BL32) -> 0 | BN26: x
BN27: x
B28: Offering Fees | E28: 0 | F28: 0 | G28: 0 | H28: 0 | I28: 0 | J28: 0 | K28: 0 | L28: 0 | M28: 0 | N28: 0 | O28: 0 | P28: 0 | Q28: 0 | R28: 0 | S28: 0 | T28: 0 | U28: 0 | V28: 0 | W28: 0 | X28: 0 | Y28: 0 | Z28: 0 | AA28: 0 | AB28: 0 | AC28: 0 | AD28: 0 | AE28: 0 | AF28: 0 | AG28: 0 | AH28: 0 | AI28: 0 | AJ28: 0 | AK28: 0 | AL28: 0 | AM28: 0 | AN28: 0 | AO28: 0 | AP28: 0 | AQ28: 0 | AR28: 0 | AS28: 0 | AT28: 0 | AU28: 0 | AV28: 0 | AW28: 0 | AX28: 0 | AY28: 0 | AZ28: 0 | BA28: 0 | BB28: 0 | BC28: 0 | BD28: 0 | BE28: 0 | BF28: 0 | BG28: 0 | BH28: 0 | BI28: 0 | BJ28: 0 | BK28: 0 | BL28: 0 | BN28: x
BN29: x
BN30: x
BN31: x
BN32: x
BN33: x
BN34: x
BN35: x
BN36: x
BN37: x
BN38: x
BN39: x
BN40: x
BN41: x

Sheet Cap Table
A1: VReeMind Inc. | B1: Expected Month: | C1: 0 | F1: Expected Month: | G1: =IF(ISTEXT('Investment & Cash'!$D$10),'Investment & Cash'!$D$10,"") -> Month 4 | J1: Expected Month: | K1: =IF(ISTEXT('Investment & Cash'!$D$11),'Investment & Cash'!$D$11,"") -> Month 13 | N1: Expected Month: | O1: =IF(ISTEXT('Investment & Cash'!$D$12),'Investment & Cash'!$D$12,"") -> Month 25 | R1: Expected Month: | S1: =IF(ISTEXT('Investment & Cash'!$D$13),'Investment & Cash'!$D$13,"") -> Month 37 | V1: Expected Month: | W1: =IF(ISTEXT('Investment & Cash'!$D$14),'Investment & Cash'!$D$14,"") -> Month 49 | Z1: Exit at Year: | AA1: 5
B3: Pre-Seed | F3: Seed | J3: Series A | N3: Series B | R3: Series C | V3: Series D | Z3: Exit
A4: Share price | C4: 0.1 | G4: 1 | K4: 1.5 | O4: 3 | S4: 10 | W4: 25 | AA4: Multiplier:
A5: Multipliers | G5: =G4/C4 -> 10 | K5: =K4/G4 -> 1.5 | O5: =O4/K4 -> 2 | S5: =S4/O4 -> 3.3333333 | W5: =W4/S4 -> 2.5 | AA5: 3
AA6: =W42*AA5 -> 681250000
B7: Net shares added this round | C7: Cumulative shareholding | D7: Ownership | F7: Net shares added this round | G7: Cumulative shareholding | H7: Ownership | J7: Net shares added this round | K7: Cumulative shareholding | L7: Ownership | N7: Net shares added this round | O7: Cumulative shareholding | P7: Ownership | R7: Net shares added this round | S7: Cumulative shareholding | T7: Ownership | V7: Net shares added this round | W7: Cumulative shareholding | X7: Ownership | AA7: Cumulative shareholding | AB7: Ownership | AF7: Founders Returns
AF8: Laurens
A9: Common stock | AD9: EBITDA | AF9: =AD11*0.25 -> 46099624
A10: Founder restricted stock | C10: =SUM(C11:C13) -> 1000000 | D10: =SUM(D11:D13) -> 1 | G10: =SUM(G11:G13) -> 1000000 | H10: =SUM(H11:H13) -> 0.74074074 | K10: =SUM(K11:K13) -> 4000000 | L10: =SUM(L11:L13) -> 0.66481994 | O10: =SUM(O11:O13) -> 5000000 | P10: =SUM(P11:P13) -> 0.61099796 | S10: =SUM(S11:S13) -> 5000000 | T10: =SUM(T11:T13) -> 0.57581574 | W10: =SUM(W11:W13) -> 5000000 | X10: =SUM(X11:X13) -> 0.55045872 | AA10: =SUM(AA11:AA13) -> 5000000 | AB10: =SUM(AB11:AB13) -> 0.55045872
A11: Founders | B11: 1000000 | C11: =B11 -> 1000000 | D11: =IFERROR(C11/C$38,0) -> 1 | F11: 0 | G11: =C11+F11 -> 1000000 | H11: =IFERROR(G11/G$38,0) -> 0.74074074 | J11: 1000000 | K11: =G11+J11 -> 2000000 | L11: =IFERROR(K11/K$38,0) -> 0.33240997 | N11: 1000000 | O11: =K11+N11 -> 3000000 | P11: =IFERROR(O11/O$38,0) -> 0.36659878 | R11: 0 | S11: =O11+R11 -> 3000000 | T11: =IFERROR(S11/S$38,0) -> 0.34548944 | V11: 0 | W11: =S11+V11 -> 3000000 | X11: =IFERROR(W11/W$38,0) -> 0.33027523 | AA11: =W11 -> 3000000 | AB11: =X11 -> 0.33027523 | AD11: =SUM(AA$6/AA$38)*AA11 -> 1.843985e+08 | AF11: Aaron
A12: Senior Leadership Team | B12: 0 | C12: =B12 -> 0 | D12: =IFERROR(C12/C$38,0) -> 0 | F12: 0 | G12: =C12+F12 -> 0 | H12: =IFERROR(G12/G$38,0) -> 0 | J12: 2000000 | K12: =G12+J12 -> 2000000 | L12: =IFERROR(K12/K$38,0) -> 0.33240997 | N12: 0 | O12: =K12+N12 -> 2000000 | P12: =IFERROR(O12/O$38,0) -> 0.24439919 | R12: 0 | S12: =O12+R12 -> 2000000 | T12: =IFERROR(S12/S$38,0) -> 0.2303263 | V12: 0 | W12: =S12+V12 -> 2000000 | X12: =IFERROR(W12/W$38,0) -> 0.22018349 | AA12: =W12 -> 2000000 | AB12: =X12 -> 0.22018349 | AD12: =SUM(AA$6/AA$38)*AA12 -> 1.2293233e+08 | AF12: =AD11*0.25 -> 46099624
A13: IP license | B13: 0 | C13: =B13 -> 0 | D13: =IFERROR(C13/C$38,0) -> 0 | F13: 0 | G13: =C13+F13 -> 0 | H13: =IFERROR(G13/G$38,0) -> 0 | J13: 0 | K13: =G13+J13 -> 0 | L13: =IFERROR(K13/K$38,0) -> 0 | N13: 0 | O13: =K13+N13 -> 0 | P13: =IFERROR(O13/O$38,0) -> 0 | R13: 0 | S13: =O13+R13 -> 0 | T13: =IFERROR(S13/S$38,0) -> 0 | V13: 0 | W13: =S13+V13 -> 0 | X13: =IFERROR(W13/W$38,0) -> 0 | AA13: =W13 -> 0 | AB13: =X13 -> 0 | AD13: =SUM(AA$6/AA$38)*AA13 -> 0
A14: Option pool | C14: =SUM(C15:C17) -> 0 | D14: =IFERROR(C14/C$38,0) -> 0 | G14: =SUM(G15:G17) -> 0 | H14: =IFERROR(G14/G$38,0) -> 0 | K14: =SUM(K15:K17) -> 1000000 | L14: =IFERROR(K14/K$38,0) -> 0.16620499 | O14: =SUM(O15:O17) -> 1000000 | P14: =IFERROR(O14/O$38,0) -> 0.12219959 | S14: =SUM(S15:S17) -> 1000000 | T14: =IFERROR(S14/S$38,0) -> 0.11516315 | W14: =SUM(W15:W17) -> 1000000 | X14: =IFERROR(W14/W$38,0) -> 0.11009174 | AA14: =SUM(AA15:AA17) -> 3000000 | AB14: =IFERROR(AA14/AA$38,0) -> 0.27067669 | AF14: Scott
A15: Staff Stock Options | B15: 0 | C15: =B15 -> 0 | D15: =IFERROR(C15/C$38,0) -> 0 | F15: 0 | G15: =C15+F15 -> 0 | H15: =IFERROR(G15/G$38,0) -> 0 | J15: 1000000 | K15: =G15+J15 -> 1000000 | L15: =IFERROR(K15/K$38,0) -> 0.16620499 | N15: 1000000 | O15: =K15+N15 -> 2000000 | P15: =IFERROR(O15/O$38,0) -> 0.24439919 | R15: 0 | S15: =O15+R15 -> 2000000 | T15: =IFERROR(S15/S$38,0) -> 0.2303263 | V15: 0 | W15: =S15+V15 -> 2000000 | X15: =IFERROR(W15/W$38,0) -> 0.22018349 | AA15: =W15 -> 2000000 | AB15: =X15 -> 0.22018349 | AD15: =SUM(AA$6/AA$38)*AA15 -> 1.2293233e+08 | AF15: =AD11*0.25 -> 46099624
A16: Issued and outstanding | B16: 0 | C16: =B16 -> 0 | D16: =IFERROR(C16/C$38,0) -> 0 | F16: 0 | G16: =C16+F16 -> 0 | H16: =IFERROR(G16/G$38,0) -> 0 | J16: 0 | K16: =G16+J16 -> 0 | L16: =IFERROR(K16/K$38,0) -> 0 | N16: 0 | O16: =K16+N16 -> 0 | P16: =IFERROR(O16/O$38,0) -> 0 | R16: 0 | S16: =O16+R16 -> 0 | T16: =IFERROR(S16/S$38,0) -> 0 | V16: 0 | W16: =S16+V16 -> 0 | X16: =IFERROR(W16/W$38,0) -> 0 | AA16: =W16 -> 0 | AB16: =X16 -> 0 | AD16: =SUM(AA$6/AA$38)*AA16 -> 0
A17: Reserved | B17: 0 | C17: =B17 -> 0 | D17: =IFERROR(C17/C$38,0) -> 0 | F17: 0 | G17: =C17+F17 -> 0 | H17: =IFERROR(G17/G$38,0) -> 0 | J17: 0 | K17: =G17+J17 -> 0 | L17: =IFERROR(K17/K$38,0) -> 0 | N17: -1000000 | O17: =K17+N17 -> -1000000 | P17: =IFERROR(O17/O$38,0) -> -0.12219959 | R17: 0 | S17: =O17+R17 -> -1000000 | T17: =IFERROR(S17/S$38,0) -> -0.11516315 | V17: 0 | W17: =S17+V17 -> -1000000 | X17: =IFERROR(W17/W$38,0) -> -0.11009174 | AA17: =W17*-1 -> 1000000 | AB17: =X17*-1 -> 0.11009174 | AD17: =SUM(AA$6/AA$38)*AA17 -> 61466165 | AF17: Sam
A18: Total | B18: =SUM(B11:B13,B15:B17) -> 1000000 | C18: =C10+C14 -> 1000000 | D18: =D10+D14 -> 1 | F18: =SUM(F11:F13,F15:F17) -> 0 | G18: =G10+G14 -> 1000000 | H18: =H10+H14 -> 0.74074074 | J18: =SUM(J11:J13,J15:J17) -> 4000000 | K18: =K10+K14 -> 5000000 | L18: =L10+L14 -> 0.83102493 | N18: =SUM(N11:N13,N15:N17) -> 1000000 | O18: =O10+O14 -> 6000000 | P18: =P10+P14 -> 0.73319756 | R18: =SUM(R11:R13,R15:R17) -> 0 | S18: =S10+S14 -> 6000000 | T18: =T10+T14 -> 0.69097889 | V18: =SUM(V11:V13,V15:V17) -> 0 | W18: =W10+W14 -> 6000000 | X18: =X10+X14 -> 0.66055046 | Z18: TOTAL | AA18: =AA10+AA14 -> 8000000 | AB18: =AB10+AB14 -> 0.82113541 | AF18: =AD11*0.25 -> 46099624
A20: Preference Stock | B20: Investment in this round | C20: Cumulative shareholding | D20: Ownership | F20: Investment in this round | G20: Cumulative shareholding | H20: Ownership | J20: Investment in this round | K20: Cumulative shareholding | L20: Ownership | N20: Investment in this round | O20: Cumulative shareholding | P20: Ownership | R20: Investment in this round | S20: Cumulative shareholding | T20: Ownership | V20: Investment in this round | W20: Cumulative shareholding | X20: Ownership | AA20: Cumulative shareholding | AB20: Ownership | AF20: CAGR | AG20: ROI | AH20: ROI Multiplier
A21: Co-Founders (pre-seed) | B21: 50000 | C21: 0 | D21: =IFERROR(C21/C$38,0) -> 0 | F21: 0 | G21: =C21+F21/G$4 -> 0 | H21: =IFERROR(G21/G$38,0) -> 0 | J21: 0 | K21: =G21+J21/K$4 -> 0 | L21: =IFERROR(K21/K$38,0) -> 0 | N21: 0 | O21: =K21+N21/O$4 -> 0 | P21: =IFERROR(O21/O$38,0) -> 0 | R21: 0 | S21: =O21+R21/S$4 -> 0 | T21: =IFERROR(S21/S$38,0) -> 0 | V21: 0 | W21: =S21+V21/W$4 -> 0 | X21: =IFERROR(W21/W$38,0) -> 0 | AA21: =W21 -> 0 | AB21: =X21 -> 0 | AD21: =SUM(AA$6/AA$38)*AA21 -> 0
A22: Seed Investor | B22: 0 | C22: =B22/C$4 -> 0 | D22: =IFERROR(C22/C$38,0) -> 0 | F22: 350000 | G22: =C22+F22/G$4 -> 350000 | H22: =IFERROR(G22/G$38,0) -> 0.25925926 | J22: 0 | K22: =G22+J22/K$4 -> 350000 | L22: =IFERROR(K22/K$38,0) -> 0.058171745 | N22: 0 | O22: =K22+N22/O$4 -> 350000 | P22: =IFERROR(O22/O$38,0) -> 0.042769857 | R22: 0 | S22: =O22+R22/S$4 -> 350000 | T22: =IFERROR(S22/S$38,0) -> 0.040307102 | V22: 0 | W22: =S22+V22/W$4 -> 350000 | X22: =IFERROR(W22/W$38,0) -> 0.03853211 | AA22: =W22 -> 350000 | AB22: =X22 -> 0.03853211 | AD22: =SUM(AA$6/AA$38)*AA22 -> 21513158 | AF22: =_xlfn.RRI(5,F22,AD22) -> 1.2789103 | AG22: =SUM(AD22-F22)/F22 -> 60.466165 | AH22: =SUM(AD22/F22) -> 61.466165
A23: Series A | B23: 0 | C23: =B23/C$4 -> 0 | D23: =IFERROR(C23/C$38,0) -> 0 | F23: 0 | G23: =C23+F23/G$4 -> 0 | H23: =IFERROR(G23/G$38,0) -> 0 | J23: 1000000 | K23: =G23+J23/K$4 -> 666666.67 | L23: =IFERROR(K23/K$38,0) -> 0.11080332 | N23: 0 | O23: =K23+N23/O$4 -> 666666.67 | P23: =IFERROR(O23/O$38,0) -> 0.081466395 | R23: 0 | S23: =O23+R23/S$4 -> 666666.67 | T23: =IFERROR(S23/S$38,0) -> 0.076775432 | V23: 0 | W23: =S23+V23/W$4 -> 666666.67 | X23: =IFERROR(W23/W$38,0) -> 0.073394495 | AA23: =W23 -> 666666.67 | AB23: =X23 -> 0.073394495 | AD23: =SUM(AA$6/AA$38)*AA23 -> 40977444 | AF23: =_xlfn.RRI(4,J23,AD23) -> 1.5300914 | AG23: =SUM(AD23-J23)/J23 -> 39.977444 | AH23: =SUM(AD23/J23) -> 40.977444
A24: Series B | B24: 0 | C24: =B24/C$4 -> 0 | D24: =IFERROR(C24/C$38,0) -> 0 | F24: 0 | G24: =C24+F24/G$4 -> 0 | H24: =IFERROR(G24/G$38,0) -> 0 | J24: 0 | K24: =G24+J24/K$4 -> 0 | L24: =IFERROR(K24/K$38,0) -> 0 | N24: 3500000 | O24: =K24+N24/O$4 -> 1166666.7 | P24: =IFERROR(O24/O$38,0) -> 0.14256619 | R24: 0 | S24: =O24+R24/S$4 -> 1166666.7 | T24: =IFERROR(S24/S$38,0) -> 0.13435701 | V24: 0 | W24: =S24+V24/W$4 -> 1166666.7 | X24: =IFERROR(W24/W$38,0) -> 0.12844037 | AA24: =W24 -> 1166666.7 | AB24: =X24 -> 0.12844037 | AD24: =SUM(AA$6/AA$38)*AA24 -> 71710526 | AF24: =_xlfn.RRI(3,N24,AD24) -> 1.7363498 | AG24: =SUM(AD24-N24)/N24 -> 19.488722 | AH24: =SUM(AD24/N24) -> 20.488722
A25: Series C | B25: 0 | C25: =B25/C$4 -> 0 | D25: =IFERROR(C25/C$38,0) -> 0 | F25: 0 | G25: =C25+F25/G$4 -> 0 | H25: =IFERROR(G25/G$38,0) -> 0 | J25: 0 | K25: =G25+J25/K$4 -> 0 | L25: =IFERROR(K25/K$38,0) -> 0 | N25: 0 | O25: =K25+N25/O$4 -> 0 | P25: =IFERROR(O25/O$38,0) -> 0 | R25: 5000000 | S25: =O25+R25/S$4 -> 500000 | T25: =IFERROR(S25/S$38,0) -> 0.057581574 | V25: 0 | W25: =S25+V25/W$4 -> 500000 | X25: =IFERROR(W25/W$38,0) -> 0.055045872 | AA25: =W25 -> 500000 | AB25: =X25 -> 0.055045872 | AD25: =SUM(AA$6/AA$38)*AA25 -> 30733083 | AF25: =_xlfn.RRI(2,R25,AD25) -> 1.4792371 | AG25: =SUM(AD25-R25)/R25 -> 5.1466165 | AH25: =SUM(AD25/R25) -> 6.1466165
A26: Series D | B26: 0 | C26: =B26/C$4 -> 0 | D26: =IFERROR(C26/C$38,0) -> 0 | F26: 0 | G26: =C26+F26/G$4 -> 0 | H26: =IFERROR(G26/G$38,0) -> 0 | J26: 0 | K26: =G26+J26/K$4 -> 0 | L26: =IFERROR(K26/K$38,0) -> 0 | N26: 0 | O26: =K26+N26/O$4 -> 0 | P26: =IFERROR(O26/O$38,0) -> 0 | R26: 0 | S26: =O26+R26/S$4 -> 0 | T26: =IFERROR(S26/S$38,0) -> 0 | V26: 10000000 | W26: =S26+V26/W$4 -> 400000 | X26: =IFERROR(W26/W$38,0) -> 0.044036697 | AA26: =W26 -> 400000 | AB26: =X26 -> 0.044036697 | AD26: =SUM(AA$6/AA$38)*AA26 -> 24586466 | AF26: =_xlfn.RRI(1,V26,AD26) -> 1.4586466 | AG26: =SUM(AD26-V26)/V26 -> 1.4586466 | AH26: =SUM(AD26/V26) -> 2.4586466
A27: Investor 7 | B27: 0 | C27: =B27/C$4 -> 0 | D27: =IFERROR(C27/C$38,0) -> 0 | F27: 0 | G27: =C27+F27/G$4 -> 0 | H27: =IFERROR(G27/G$38,0) -> 0 | J27: 0 | K27: =G27+J27/K$4 -> 0 | L27: =IFERROR(K27/K$38,0) -> 0 | N27: 0 | O27: =K27+N27/O$4 -> 0 | P27: =IFERROR(O27/O$38,0) -> 0 | R27: 0 | S27: =O27+R27/S$4 -> 0 | T27: =IFERROR(S27/S$38,0) -> 0 | V27: 0 | W27: =S27+V27/W$4 -> 0 | X27: =IFERROR(W27/W$38,0) -> 0 | AA27: =W27 -> 0 | AB27: =X27 -> 0 | AD27: =SUM(AA$6/AA$38)*AA27 -> 0 | AF27: =AVERAGE(AF22:AF26) -> 1.496647 | AG27: =AVERAGE(AG22:AG26) -> 25.307519 | AH27: =AVERAGE(AH22:AH26) -> 26.307519
A28: Investor 8 | B28: 0 | C28: =B28/C$4 -> 0 | D28: =IFERROR(C28/C$38,0) -> 0 | F28: 0 | G28: =C28+F28/G$4 -> 0 | H28: =IFERROR(G28/G$38,0) -> 0 | J28: 0 | K28: =G28+J28/K$4 -> 0 | L28: =IFERROR(K28/K$38,0) -> 0 | N28: 0 | O28: =K28+N28/O$4 -> 0 | P28: =IFERROR(O28/O$38,0) -> 0 | R28: 0 | S28: =O28+R28/S$4 -> 0 | T28: =IFERROR(S28/S$38,0) -> 0 | V28: 0 | W28: =S28+V28/W$4 -> 0 | X28: =IFERROR(W28/W$38,0) -> 0 | AA28: =W28 -> 0 | AB28: =X28 -> 0 | AD28: =SUM(AA$6/AA$38)*AA28 -> 0
A29: Investor 9 | B29: 0 | C29: =B29/C$4 -> 0 | D29: =IFERROR(C29/C$38,0) -> 0 | F29: 0 | G29: =C29+F29/G$4 -> 0 | H29: =IFERROR(G29/G$38,0) -> 0 | J29: 0 | K29: =G29+J29/K$4 -> 0 | L29: =IFERROR(K29/K$38,0) -> 0 | N29: 0 | O29: =K29+N29/O$4 -> 0 | P29: =IFERROR(O29/O$38,0) -> 0 | R29: 0 | S29: =O29+R29/S$4 -> 0 | T29: =IFERROR(S29/S$38,0) -> 0 | V29: 0 | W29: =S29+V29/W$4 -> 0 | X29: =IFERROR(W29/W$38,0) -> 0 | AA29: =W29 -> 0 | AB29: =X29 -> 0 | AD29: =SUM(AA$6/AA$38)*AA29 -> 0
A30: Investor 10 | B30: 0 | C30: =B30/C$4 -> 0 | D30: =IFERROR(C30/C$38,0) -> 0 | F30: 0 | G30: =C30+F30/G$4 -> 0 | H30: =IFERROR(G30/G$38,0) -> 0 | J30: 0 | K30: =G30+J30/K$4 -> 0 | L30: =IFERROR(K30/K$38,0) -> 0 | N30: 0 | O30: =K30+N30/O$4 -> 0 | P30: =IFERROR(O30/O$38,0) -> 0 | R30: 0 | S30: =O30+R30/S$4 -> 0 | T30: =IFERROR(S30/S$38,0) -> 0 | V30: 0 | W30: =S30+V30/W$4 -> 0 | X30: =IFERROR(W30/W$38,0) -> 0 | AA30: =W30 -> 0 | AB30: =X30 -> 0 | AD30: =SUM(AA$6/AA$38)*AA30 -> 0
A31: Investor 11 | B31: 0 | C31: =B31/C$4 -> 0 | D31: =IFERROR(C31/C$38,0) -> 0 | F31: 0 | G31: =C31+F31/G$4 -> 0 | H31: =IFERROR(G31/G$38,0) -> 0 | J31: 0 | K31: =G31+J31/K$4 -> 0 | L31: =IFERROR(K31/K$38,0) -> 0 | N31: 0 | O31: =K31+N31/O$4 -> 0 | P31: =IFERROR(O31/O$38,0) -> 0 | R31: 0 | S31: =O31+R31/S$4 -> 0 | T31: =IFERROR(S31/S$38,0) -> 0 | V31: 0 | W31: =S31+V31/W$4 -> 0 | X31: =IFERROR(W31/W$38,0) -> 0 | AA31: =W31 -> 0 | AB31: =X31 -> 0 | AD31: =SUM(AA$6/AA$38)*AA31 -> 0
A32: Investor 12 | B32: 0 | C32: =B32/C$4 -> 0 | D32: =IFERROR(C32/C$38,0) -> 0 | F32: 0 | G32: =C32+F32/G$4 -> 0 | H32: =IFERROR(G32/G$38,0) -> 0 | J32: 0 | K32: =G32+J32/K$4 -> 0 | L32: =IFERROR(K32/K$38,0) -> 0 | N32: 0 | O32: =K32+N32/O$4 -> 0 | P32: =IFERROR(O32/O$38,0) -> 0 | R32: 0 | S32: =O32+R32/S$4 -> 0 | T32: =IFERROR(S32/S$38,0) -> 0 | V32: 0 | W32: =S32+V32/W$4 -> 0 | X32: =IFERROR(W32/W$38,0) -> 0 | AA32: =W32 -> 0 | AB32: =X32 -> 0 | AD32: =SUM(AA$6/AA$38)*AA32 -> 0
A33: Investor 13 | B33: 0 | C33: =B33/C$4 -> 0 | D33: =IFERROR(C33/C$38,0) -> 0 | F33: 0 | G33: =C33+F33/G$4 -> 0 | H33: =IFERROR(G33/G$38,0) -> 0 | J33: 0 | K33: =G33+J33/K$4 -> 0 | L33: =IFERROR(K33/K$38,0) -> 0 | N33: 0 | O33: =K33+N33/O$4 -> 0 | P33: =IFERROR(O33/O$38,0) -> 0 | R33: 0 | S33: =O33+R33/S$4 -> 0 | T33: =IFERROR(S33/S$38,0) -> 0 | V33: 0 | W33: =S33+V33/W$4 -> 0 | X33: =IFERROR(W33/W$38,0) -> 0 | AA33: =W33 -> 0 | AB33: =X33 -> 0 | AD33: =SUM(AA$6/AA$38)*AA33 -> 0
A34: Investor 14 | B34: 0 | C34: =B34/C$4 -> 0 | D34: =IFERROR(C34/C$38,0) -> 0 | F34: 0 | G34: =C34+F34/G$4 -> 0 | H34: =IFERROR(G34/G$38,0) -> 0 | J34: 0 | K34: =G34+J34/K$4 -> 0 | L34: =IFERROR(K34/K$38,0) -> 0 | N34: 0 | O34: =K34+N34/O$4 -> 0 | P34: =IFERROR(O34/O$38,0) -> 0 | R34: 0 | S34: =O34+R34/S$4 -> 0 | T34: =IFERROR(S34/S$38,0) -> 0 | V34: 0 | W34: =S34+V34/W$4 -> 0 | X34: =IFERROR(W34/W$38,0) -> 0 | AA34: =W34 -> 0 | AB34: =X34 -> 0 | AD34: =SUM(AA$6/AA$38)*AA34 -> 0
A35: Investor 15 | B35: 0 | C35: =B35/C$4 -> 0 | D35: =IFERROR(C35/C$38,0) -> 0 | F35: 0 | G35: =C35+F35/G$4 -> 0 | H35: =IFERROR(G35/G$38,0) -> 0 | J35: 0 | K35: =G35+J35/K$4 -> 0 | L35: =IFERROR(K35/K$38,0) -> 0 | N35: 0 | O35: =K35+N35/O$4 -> 0 | P35: =IFERROR(O35/O$38,0) -> 0 | R35: 0 | S35: =O35+R35/S$4 -> 0 | T35: =IFERROR(S35/S$38,0) -> 0 | V35: 0 | W35: =S35+V35/W$4 -> 0 | X35: =IFERROR(W35/W$38,0) -> 0 | AA35: =W35 -> 0 | AB35: =X35 -> 0 | AD35: =SUM(AA$6/AA$38)*AA35 -> 0
A36: Total | B36: =SUM(B21:B35) -> 50000 | C36: =SUM(C21:C35) -> 0 | D36: =SUM(D21:D35) -> 0 | F36: =SUM(F21:F35) -> 350000 | G36: =SUM(G21:G35) -> 350000 | H36: =SUM(H21:H35) -> 0.25925926 | J36: =SUM(J21:J35) -> 1000000 | K36: =SUM(K21:K35) -> 1016666.7 | L36: =SUM(L21:L35) -> 0.16897507 | N36: =SUM(N21:N35) -> 3500000 | O36: =SUM(O21:O35) -> 2183333.3 | P36: =SUM(P21:P35) -> 0.26680244 | R36: =SUM(R21:R35) -> 5000000 | S36: =SUM(S21:S35) -> 2683333.3 | T36: =SUM(T21:T35) -> 0.30902111 | V36: =SUM(V21:V35) -> 10000000 | W36: =SUM(W21:W35) -> 3083333.3 | X36: =SUM(X21:X35) -> 0.33944954 | AA36: =SUM(AA21:AA35) -> 3083333.3 | AB36: =SUM(AB21:AB35) -> 0.33944954
A38: Total allocated shares | C38: =C18+C36 -> 1000000 | D38: =D18+D36 -> 1 | G38: =G18+G36 -> 1350000 | H38: =H18+H36 -> 1 | K38: =K18+K36 -> 6016666.7 | L38: =L18+L36 -> 1 | O38: =O18+O36 -> 8183333.3 | P38: =IFERROR(P18+P36,0) -> 1 | S38: =S18+S36 -> 8683333.3 | T38: =IFERROR(T18+T36,0) -> 1 | W38: =W18+W36 -> 9083333.3 | X38: =IFERROR(X18+X36,0) -> 1 | Z38: TOTAL | AA38: =AA18+AA36 -> 11083333 | AB38: =IFERROR(AB18+AB36,0) -> 1.1605849
A40: Pre-money valuation | C40: =C4*C18 -> 100000 | G40: =IF((G18+C36)*G4=0,C42,(G18+C36)*G4) -> 1000000 | K40: =(K18+G36)*K4 -> 8025000 | O40: =(O18+K36)*O4 -> 21050000 | S40: =(S18+O36)*S4 -> 81833333 | W40: =(W18+S36)*W4 -> 2.1708333e+08
A42: Post-money valuation | C42: =C38*C4 -> 100000 | G42: =G38*G4 -> 1350000 | K42: =K38*K4 -> 9025000 | O42: =O38*O4 -> 24550000 | S42: =S38*S4 -> 86833333 | W42: =W38*W4 -> 2.2708333e+08
A44: Difference | C44: =SUM(C42-C40) -> 0 | G44: =SUM(G42-G40) -> 350000 | K44: =SUM(K42-K40) -> 1000000 | O44: =SUM(O42-O40) -> 3500000 | S44: =SUM(S42-S40) -> 5000000 | W44: =SUM(W42-W40) -> 10000000

Sheet ROI Analysis
A1: Original | B1: Average | C1: Bin | D1: Random | E1: Norm Dist | F1: Histogram | G1: Histogram | P1: CAGR | Q1: Probability Distribution
A2: =P2 -> 1.2789103 | B2: =AVERAGE(A2:A6) -> 1.496647 | C2: =$B$2-3*$B4 -> 1.0043078 | D2: 0.9418396 | E2: =_xlfn.NORM.DIST(D2,$B$2,$B$4,FALSE) -> 0.0080176748 | F2: Bin | G2: Frequency | H2: Bin | I2: Frequency | P2: ='Cap Table'!AF22 -> 1.2789103 | Q2: =_xlfn.NORM.DIST(P2,$N$6,$N$7,0) -> 0.71513141
A3: =P3 -> 1.4586466 | B3: STDEV | C3: =C2+$B$4 -> 1.1684209 | D3: 0.99879718 | E3: =_xlfn.NORM.DIST(D3,$B$2,$B$4,FALSE) -> 0.024403283 | F3: 1.0043078 | G3: 2 | H3: 1.0043078 | I3: 0 | P3: ='Cap Table'!AF26 -> 1.4586466 | Q3: =_xlfn.NORM.DIST(P3,$N$6,$N$7,0) -> 3.0180939
A4: =P4 -> 1.4792371 | B4: =STDEV(A2:A6) -> 0.16411308 | C4: =C3+$B$4 -> 1.332534 | D4: 1.0148217 | E4: =_xlfn.NORM.DIST(D4,$B$2,$B$4,FALSE) -> 0.032660264 | F4: 1.1684209 | G4: 40 | H4: 1.1684209 | I4: 0 | P4: ='Cap Table'!AF25 -> 1.4792371 | Q4: =_xlfn.NORM.DIST(P4,$N$6,$N$7,0) -> 3.1279138
A5: =P5 -> 1.5300914 | C5: =C4+$B$4 -> 1.496647 | D5: 1.0222489 | E5: =_xlfn.NORM.DIST(D5,$B$2,$B$4,FALSE) -> 0.037263156 | F5: 1.332534 | G5: 265 | H5: 1.332534 | I5: 1 | P5: ='Cap Table'!AF23 -> 1.5300914 | Q5: =_xlfn.NORM.DIST(P5,$N$6,$N$7,0) -> 3.0490264
A6: =P6 -> 1.7363498 | C6: =C5+$B$4 -> 1.6607601 | D6: 1.056119 | E6: =_xlfn.NORM.DIST(D6,$B$2,$B$4,FALSE) -> 0.066240596 | F6: 1.496647 | G6: 696 | H6: 1.496647 | I6: 2 | M6: Mean | N6: ='Cap Table'!AF27 -> 1.496647 | P6: ='Cap Table'!AF24 -> 1.7363498 | Q6: =_xlfn.NORM.DIST(P6,$N$6,$N$7,0) -> 0.52201558
C7: =C6+$B$4 -> 1.8248732 | D7: 1.0745018 | E7: =_xlfn.NORM.DIST(D7,$B$2,$B$4,FALSE) -> 0.088916429 | F7: 1.6607601 | G7: 666 | H7: 1.6607601 | I7: 1 | M7: Std Dev | N7: =_xlfn.STDEV.P('ROI Analysis'!AR22,'ROI Analysis'!AR23,'Cap Table'!AF24,'Cap Table'!AF25,'Cap Table'!AF26) -> 0.1263373
C8: =C7+$B$4 -> 1.9889863 | D8: 1.0755765 | E8: =_xlfn.NORM.DIST(D8,$B$2,$B$4,FALSE) -> 0.090424904 | F8: 1.8248732 | G8: 274 | H8: 1.8248732 | I8: 1
D9: 1.0803707 | E9: =_xlfn.NORM.DIST(D9,$B$2,$B$4,FALSE) -> 0.097421381 | F9: 1.9889863 | G9: 49 | H9: 1.9889863 | I9: 0
D10: 1.0881322 | E10: =_xlfn.NORM.DIST(D10,$B$2,$B$4,FALSE) -> 0.1097153 | F10: More | G10: 8 | H10: More | I10: 0
D11: 1.0948071 | E11: =_xlfn.NORM.DIST(D11,$B$2,$B$4,FALSE) -> 0.12130464
D12: 1.0979117 | E12: =_xlfn.NORM.DIST(D12,$B$2,$B$4,FALSE) -> 0.12703296
D13: 1.1006342 | E13: =_xlfn.NORM.DIST(D13,$B$2,$B$4,FALSE) -> 0.1322395
D14: 1.1025448 | E14: =_xlfn.NORM.DIST(D14,$B$2,$B$4,FALSE) -> 0.13599777
D15: 1.1059927 | E15: =_xlfn.NORM.DIST(D15,$B$2,$B$4,FALSE) -> 0.14300359
D16: 1.1107541 | E16: =_xlfn.NORM.DIST(D16,$B$2,$B$4,FALSE) -> 0.15316427
D17: 1.1128138 | E17: =_xlfn.NORM.DIST(D17,$B$2,$B$4,FALSE) -> 0.15773944
D18: 1.1259248 | E18: =_xlfn.NORM.DIST(D18,$B$2,$B$4,FALSE) -> 0.1895405
D19: 1.1303399 | E19: =_xlfn.NORM.DIST(D19,$B$2,$B$4,FALSE) -> 0.20134359
D20: 1.1309728 | E20: =_xlfn.NORM.DIST(D20,$B$2,$B$4,FALSE) -> 0.20308259
D21: 1.134355 | E21: =_xlfn.NORM.DIST(D21,$B$2,$B$4,FALSE) -> 0.21258063
D22: 1.1355461 | E22: =_xlfn.NORM.DIST(D22,$B$2,$B$4,FALSE) -> 0.21600835
... D2001: 2.0926454 | E2001: =_xlfn.NORM.DIST(D2001,$B$2,$B$4,FALSE) -> 0.0033255648

Sheet Costs
C1: 24 Months Total Costs | D1: Year | E1: 2021 | Q1: =E1+1 -> 2022 | AC1: =Q1+1 -> 2023 | AO1: =AC1+1 -> 2024 | BA1: =AO1+1 -> 2025
C2: =SUM(E4:AN4) -> -6160771.7 | D2: Month | E2: 1 | F2: =E2+1 -> 2 | G2: =F2+1 -> 3 | H2: =G2+1 -> 4 | I2: =H2+1 -> 5 | J2: =I2+1 -> 6 | K2: =J2+1 -> 7 | L2: =K2+1 -> 8 | M2: =L2+1 -> 9 | ... BL2: =BK2+1 -> 60
D4: TOTAL COSTS | E4: =SUM(E8+E16) -> -95867.656 | F4: =SUM(F8+F16) -> -47427.656 | G4: =SUM(G8+G16) -> -50977.656 | H4: =SUM(H8+H16) -> -60646.573 | I4: =SUM(I8+I16) -> -71546.573 | J4: =SUM(J8+J16) -> -59421.573 | K4: =SUM(K8+K16) -> -97494.025 | L4: =SUM(L8+L16) -> -80749.025 | ... BL4: =SUM(BL8+BL16) -> -770122.71
B6: Type | C6: Category | D6: Unit Cost
B8: CAPEX | D8: Sub Total | E8: =E10 -> -20000 | F8: =F10 -> 0 | G8: =G10 -> 0 | H8: =H10 -> -5000 | I8: =I10 -> 0 | J8: =J10 -> 0 | K8: =K10 -> -15000 | L8: =L10 -> 0 | ... BL8: =BL10 -> 0
B10: =SUM(E10:AN10) -> -110000 | C10: Equipment | E10: =SUM(E11:E13) -> -20000 | F10: =SUM(F11:F13) -> 0 | G10: =SUM(G11:G13) -> 0 | H10: =SUM(H11:H13) -> -5000 | I10: =SUM(I11:I13) -> 0 | J10: =SUM(J11:J13) -> 0 | K10: =SUM(K11:K13) -> -15000 | L10: =SUM(L11:L13) -> 0 | ... BL10: =SUM(BL11:BL13) -> 0
C11: WFH Package | D11: -5000 | E11: =SUM(E17*$D$11) -> -20000 | F11: =SUM(F17*$D$11) -> 0 | G11: =SUM(G17*$D$11) -> 0 | H11: =SUM(H17*$D$11) -> -5000 | I11: =SUM(I17*$D$11) -> 0 | J11: =SUM(J17*$D$11) -> 0 | K11: =SUM(K17*$D$11) -> -15000 | L11: =SUM(L17*$D$11) -> 0 | ... BL11: =SUM(BL17*$D$11) -> 0
B16: OPEX | D16: Sub Total | E16: =SUM(E18,E70,E80,E88,E101,E110,E118,E125,E132,E147,E155) -> -75867.656 | F16: =SUM(F18,F70,F80,F88,F101,F110,F118,F125,F132,F147,F155) -> -47427.656 | G16: =SUM(G18,G70,G80,G88,G101,G110,G118,G125,G132,G147,G155) -> -50977.656 | H16: =SUM(H18,H70,H80,H88,H101,H110,H118,H125,H132,H147,H155) -> -55646.573 | I16: =SUM(I18,I70,I80,I88,I101,I110,I118,I125,I132,I147,I155) -> -71546.573 | J16: =SUM(J18,J70,J80,J88,J101,J110,J118,J125,J132,J147,J155) -> -59421.573 | K16: =SUM(K18,K70,K80,K88,K101,K110,K118,K125,K132,K147,K155) -> -82494.025 | L16: =SUM(L18,L70,L80,L88,L101,L110,L118,L125,L132,L147,L155) -> -80749.025 | ... BL16: =SUM(BL18,BL70,BL80,BL88,BL101,BL110,BL118,BL125,BL132,BL147,BL155) -> -770122.71
C17: # of new hires | E17: =SUM(COUNTIF(E$19:E$58,"<0")) -> 4 | F17: =SUM(COUNTIF(F$19:F$58,"<0"))-(COUNTIF(E$19:E$58,"<0")) -> 0 | G17: =SUM(COUNTIF(G$19:G$58,"<0"))-(COUNTIF(F$19:F$58,"<0")) -> 0 | H17: =SUM(COUNTIF(H$19:H$58,"<0"))-(COUNTIF(G$19:G$58,"<0")) -> 1 | I17: =SUM(COUNTIF(I$19:I$58,"<0"))-(COUNTIF(H$19:H$58,"<0")) -> 0 | J17: =SUM(COUNTIF(J$19:J$58,"<0"))-(COUNTIF(I$19:I$58,"<0")) -> 0 | K17: =SUM(COUNTIF(K$19:K$58,"<0"))-(COUNTIF(J$19:J$58,"<0")) -> 3 | L17: =SUM(COUNTIF(L$19:L$58,"<0"))-(COUNTIF(K$19:K$58,"<0")) -> 0 | M17: =SUM(COUNTIF(M$19:M$58,"<0"))-(COUNTIF(L$19:L$58,"<0")) -> 0 | ... BL17: =SUM(COUNTIF(BL$19:BL$58,"<0"))-(COUNTIF(BK$19:BK$58,"<0")) -> 0
B18: =SUM(E18:AN18) -> -3196460 | C18: HR | E18: =SUM(E19:E68) -> -20382.133 | F18: =SUM(F19:F68) -> -14382.133 | G18: =SUM(G19:G68) -> -14382.133 | H18: =SUM(H19:H68) -> -20435.333 | I18: =SUM(I19:I68) -> -20435.333 | J18: =SUM(J19:J68) -> -20435.333 | K18: =SUM(K19:K68) -> -38594.933 | L18: =SUM(L19:L68) -> -38594.933 | ... BL18: =SUM(BL19:BL68) -> -424814.67
C19: CEO | D19: -38000 | E19: =SUM($D19/12) -> -3166.6667 | F19: =SUM($D19/12) -> -3166.6667 | G19: =SUM($D19/12) -> -3166.6667 | H19: =SUM($D19/12) -> -3166.6667 | I19: =SUM($D19/12) -> -3166.6667 | J19: =SUM($D19/12) -> -3166.6667 | K19: =SUM($D19/12) -> -3166.6667 | L19: =SUM($D19/12) -> -3166.6667 | ... P19: =SUM($D19/12) -> -3166.6667 | Q19: =SUM($D19/12)*1.5 -> -4750 | R19: =SUM($D19/12)*1.5 -> -4750 | S19: =SUM($D19/12)*1.5 -> -4750 | T19: =SUM($D19/12)*1.5 -> -4750 | U19: =SUM($D19/12)*1.5 -> -4750 | V19: =SUM($D19/12)*1.5 -> -4750 | W19: =SUM($D19/12)*1.5 -> -4750 | X19: =SUM($D19/12)*1.5 -> -4750 | Y19: =SUM($D19/12)*1.5 -> -4750 | Z19: =SUM($D19/12) -> -3166.6667 | AA19: =SUM($D19/12) -> -3166.6667 | AB19: =SUM($D19/12) -> -3166.6667 | AC19: =SUM($D19/12)*2.5 -> -7916.6667 | AD19: =SUM($D19/12)*2.5 -> -7916.6667 | AE19: =SUM($D19/12)*2.5 -> -7916.6667 | AF19: =SUM($D19/12)*2.5 -> -7916.6667 | AG19: =SUM($D19/12)*2.5 -> -7916.6667 | AH19: =SUM($D19/12)*2.5 -> -7916.6667 | AI19: =SUM($D19/12)*2.5 -> -7916.6667 | AJ19: =SUM($D19/12)*2.5 -> -7916.6667 | ... AN19: =SUM($D19/12)*2.5 -> -7916.6667 | AO19: =SUM($D19/12)*4 -> -12666.667 | AP19: =SUM($D19/12)*4 -> -12666.667 | AQ19: =SUM($D19/12)*4 -> -12666.667 | AR19: =SUM($D19/12)*4 -> -12666.667 | AS19: =SUM($D19/12)*4 -> -12666.667 | AT19: =SUM($D19/12)*4 -> -12666.667 | AU19: =SUM($D19/12)*4 -> -12666.667 | AV19: =SUM($D19/12)*4 -> -12666.667 | ... AZ19: =SUM($D19/12)*4 -> -12666.667 | BA19: =SUM($D19/12)*5 -> -15833.333 | BB19: =SUM($D19/12)*5 -> -15833.333 | BC19: =SUM($D19/12)*5 -> -15833.333 | BD19: =SUM($D19/12)*5 -> -15833.333 | BE19: =SUM($D19/12)*5 -> -15833.333 | BF19: =SUM($D19/12)*5 -> -15833.333 | BG19: =SUM($D19/12)*5 -> -15833.333 | BH19: =SUM($D19/12)*5 -> -15833.333 | ... BL19: =SUM($D19/12)*5 -> -15833.333
C20: CTO | D20: -35000 | E20: =SUM($D20/12) -> -2916.6667 | F20: =SUM($D20/12) -> -2916.6667 | G20: =SUM($D20/12) -> -2916.6667 | H20: =SUM($D20/12) -> -2916.6667 | I20: =SUM($D20/12) -> -2916.6667 | J20: =SUM($D20/12) -> -2916.6667 | K20: =SUM($D20/12) -> -2916.6667 | L20: =SUM($D20/12) -> -2916.6667 | ... P20: =SUM($D20/12) -> -2916.6667 | Q20: =SUM($D20/12)*1.5 -> -4375 | R20: =SUM($D20/12)*1.5 -> -4375 | S20: =SUM($D20/12)*1.5 -> -4375 | T20: =SUM($D20/12)*1.5 -> -4375 | U20: =SUM($D20/12)*1.5 -> -4375 | V20: =SUM($D20/12)*1.5 -> -4375 | W20: =SUM($D20/12)*1.5 -> -4375 | X20: =SUM($D20/12)*1.5 -> -4375 | Y20: =SUM($D20/12)*1.5 -> -4375 | Z20: =SUM($D20/12) -> -2916.6667 | AA20: =SUM($D20/12) -> -2916.6667 | AB20: =SUM($D20/12) -> -2916.6667 | AC20: =SUM($D20/12)*2.5 -> -7291.6667 | AD20: =SUM($D20/12)*2.5 -> -7291.6667 | AE20: =SUM($D20/12)*2.5 -> -7291.6667 | AF20: =SUM($D20/12)*2.5 -> -7291.6667 | AG20: =SUM($D20/12)*2.5 -> -7291.6667 | AH20: =SUM($D20/12)*2.5 -> -7291.6667 | AI20: =SUM($D20/12)*2.5 -> -7291.6667 | AJ20: =SUM($D20/12)*2.5 -> -7291.6667 | ... AN20: =SUM($D20/12)*2.5 -> -7291.6667 | AO20: =SUM($D20/12)*4 -> -11666.667 | AP20: =SUM($D20/12)*4 -> -11666.667 | AQ20: =SUM($D20/12)*4 -> -11666.667 | AR20: =SUM($D20/12)*4 -> -11666.667 | AS20: =SUM($D20/12)*4 -> -11666.667 | AT20: =SUM($D20/12)*4 -> -11666.667 | AU20: =SUM($D20/12)*4 -> -11666.667 | AV20: =SUM($D20/12)*4 -> -11666.667 | ... AZ20: =SUM($D20/12)*4 -> -11666.667 | BA20: =SUM($D20/12)*5 -> -14583.333 | BB20: =SUM($D20/12)*5 -> -14583.333 | BC20: =SUM($D20/12)*5 -> -14583.333 | BD20: =SUM($D20/12)*5 -> -14583.333 | BE20: =SUM($D20/12)*5 -> -14583.333 | BF20: =SUM($D20/12)*5 -> -14583.333 | BG20: =SUM($D20/12)*5 -> -14583.333 | BH20: =SUM($D20/12)*5 -> -14583.333 | ... BL20: =SUM($D20/12)*5 -> -14583.333
C21: CFO | D21: -32000 | E21: =SUM($D21/12) -> -2666.6667 | F21: =SUM($D21/12) -> -2666.6667 | G21: =SUM($D21/12) -> -2666.6667 | H21: =SUM($D21/12) -> -2666.6667 | I21: =SUM($D21/12) -> -2666.6667 | J21: =SUM($D21/12) -> -2666.6667 | K21: =SUM($D21/12) -> -2666.6667 | L21: =SUM($D21/12) -> -2666.6667 | ... P21: =SUM($D21/12) -> -2666.6667 | Q21: =SUM($D21/12)*1.5 -> -4000 | R21: =SUM($D21/12)*1.5 -> -4000 | S21: =SUM($D21/12)*1.5 -> -4000 | T21: =SUM($D21/12)*1.5 -> -4000 | U21: =SUM($D21/12)*1.5 -> -4000 | V21: =SUM($D21/12)*1.5 -> -4000 | W21: =SUM($D21/12)*1.5 -> -4000 | X21: =SUM($D21/12)*1.5 -> -4000 | Y21: =SUM($D21/12)*1.5 -> -4000 | Z21: =SUM($D21/12) -> -2666.6667 | AA21: =SUM($D21/12) -> -2666.6667 | AB21: =SUM($D21/12) -> -2666.6667 | AC21: =SUM($D21/12)*2.5 -> -6666.6667 | AD21: =SUM($D21/12)*2.5 -> -6666.6667 | AE21: =SUM($D21/12)*2.5 -> -6666.6667 | AF21: =SUM($D21/12)*2.5 -> -6666.6667 | AG21: =SUM($D21/12)*2.5 -> -6666.6667 | AH21: =SUM($D21/12)*2.5 -> -6666.6667 | AI21: =SUM($D21/12)*2.5 -> -6666.6667 | AJ21: =SUM($D21/12)*2.5 -> -6666.6667 | ... AN21: =SUM($D21/12)*2.5 -> -6666.6667 | AO21: =SUM($D21/12)*4 -> -10666.667 | AP21: =SUM($D21/12)*4 -> -10666.667 | AQ21: =SUM($D21/12)*4 -> -10666.667 | AR21: =SUM($D21/12)*4 -> -10666.667 | AS21: =SUM($D21/12)*4 -> -10666.667 | AT21: =SUM($D21/12)*4 -> -10666.667 | AU21: =SUM($D21/12)*4 -> -10666.667 | AV21: =SUM($D21/12)*4 -> -10666.667 | ... AZ21: =SUM($D21/12)*4 -> -10666.667 | BA21: =SUM($D21/12)*5 -> -13333.333 | BB21: =SUM($D21/12)*5 -> -13333.333 | BC21: =SUM($D21/12)*5 -> -13333.333 | BD21: =SUM($D21/12)*5 -> -13333.333 | BE21: =SUM($D21/12)*5 -> -13333.333 | BF21: =SUM($D21/12)*5 -> -13333.333 | BG21: =SUM($D21/12)*5 -> -13333.333 | BH21: =SUM($D21/12)*5 -> -13333.333 | ... BL21: =SUM($D21/12)*5 -> -13333.333
C22: CMO | D22: -34000 | E22: =SUM($D22/12) -> -2833.3333 | F22: =SUM($D22/12) -> -2833.3333 | G22: =SUM($D22/12) -> -2833.3333 | H22: =SUM($D22/12) -> -2833.3333 | I22: =SUM($D22/12) -> -2833.3333 | J22: =SUM($D22/12) -> -2833.3333 | K22: =SUM($D22/12) -> -2833.3333 | L22: =SUM($D22/12) -> -2833.3333 | ... P22: =SUM($D22/12) -> -2833.3333 | Q22: =SUM($D22/12)*1.5 -> -4250 | R22: =SUM($D22/12)*1.5 -> -4250 | S22: =SUM($D22/12)*1.5 -> -4250 | T22: =SUM($D22/12)*1.5 -> -4250 | U22: =SUM($D22/12)*1.5 -> -4250 | V22: =SUM($D22/12)*1.5 -> -4250 | W22: =SUM($D22/12)*1.5 -> -4250 | X22: =SUM($D22/12)*1.5 -> -4250 | Y22: =SUM($D22/12)*1.5 -> -4250 | Z22: =SUM($D22/12) -> -2833.3333 | AA22: =SUM($D22/12) -> -2833.3333 | AB22: =SUM($D22/12) -> -2833.3333 | AC22: =SUM($D22/12)*2.5 -> -7083.3333 | AD22: =SUM($D22/12)*2.5 -> -7083.3333 | AE22: =SUM($D22/12)*2.5 -> -7083.3333 | AF22: =SUM($D22/12)*2.5 -> -7083.3333 | AG22: =SUM($D22/12)*2.5 -> -7083.3333 | AH22: =SUM($D22/12)*2.5 -> -7083.3333 | AI22: =SUM($D22/12)*2.5 -> -7083.3333 | AJ22: =SUM($D22/12)*2.5 -> -7083.3333 | ... AN22: =SUM($D22/12)*2.5 -> -7083.3333 | AO22: =SUM($D22/12)*4 -> -11333.333 | AP22: =SUM($D22/12)*4 -> -11333.333 | AQ22: =SUM($D22/12)*4 -> -11333.333 | AR22: =SUM($D22/12)*4 -> -11333.333 | AS22: =SUM($D22/12)*4 -> -11333.333 | AT22: =SUM($D22/12)*4 -> -11333.333 | AU22: =SUM($D22/12)*4 -> -11333.333 | AV22: =SUM($D22/12)*4 -> -11333.333 | ... AZ22: =SUM($D22/12)*4 -> -11333.333 | BA22: =SUM($D22/12)*5 -> -14166.667 | BB22: =SUM($D22/12)*5 -> -14166.667 | BC22: =SUM($D22/12)*5 -> -14166.667 | BD22: =SUM($D22/12)*5 -> -14166.667 | BE22: =SUM($D22/12)*5 -> -14166.667 | BF22: =SUM($D22/12)*5 -> -14166.667 | BG22: =SUM($D22/12)*5 -> -14166.667 | BH22: =SUM($D22/12)*5 -> -14166.667 | ... BL22: =SUM($D22/12)*5 -> -14166.667
C23: VR Dev 1 | D23: -60000 | H23: =SUM($D23/12) -> -5000 | I23: =SUM($D23/12) -> -5000 | J23: =SUM($D23/12) -> -5000 | K23: =SUM($D23/12) -> -5000 | L23: =SUM($D23/12) -> -5000 | M23: =SUM($D23/12) -> -5000 | N23: =SUM($D23/12) -> -5000 | O23: =SUM($D23/12) -> -5000 | ... BL23: =SUM($D23/12) -> -5000
C24: VR Dev 2 | D24: -60000 | K24: =SUM($D24/12) -> -5000 | L24: =SUM($D24/12) -> -5000 | M24: =SUM($D24/12) -> -5000 | N24: =SUM($D24/12) -> -5000 | O24: =SUM($D24/12) -> -5000 | P24: =SUM($D24/12) -> -5000 | Q24: =SUM($D24/12) -> -5000 | R24: =SUM($D24/12) -> -5000 | ... BL24: =SUM($D24/12) -> -5000
C25: VR Dev 3 | D25: -60000 | Q25: =SUM($D25/12) -> -5000 | R25: =SUM($D25/12) -> -5000 | S25: =SUM($D25/12) -> -5000 | T25: =SUM($D25/12) -> -5000 | U25: =SUM($D25/12) -> -5000 | V25: =SUM($D25/12) -> -5000 | W25: =SUM($D25/12) -> -5000 | X25: =SUM($D25/12) -> -5000 | ... BL25: =SUM($D25/12) -> -5000
C26: VR Dev 4 | D26: -60000 | Q26: =SUM($D26/12) -> -5000 | R26: =SUM($D26/12) -> -5000 | S26: =SUM($D26/12) -> -5000 | T26: =SUM($D26/12) -> -5000 | U26: =SUM($D26/12) -> -5000 | V26: =SUM($D26/12) -> -5000 | W26: =SUM($D26/12) -> -5000 | X26: =SUM($D26/12) -> -5000 | ... BL26: =SUM($D26/12) -> -5000
C27: Cloud Engineer 1 | D27: -60000 | K27: =SUM($D27/12) -> -5000 | L27: =SUM($D27/12) -> -5000 | M27: =SUM($D27/12) -> -5000 | N27: =SUM($D27/12) -> -5000 | O27: =SUM($D27/12) -> -5000 | P27: =SUM($D27/12) -> -5000 | Q27: =SUM($D27/12) -> -5000 | R27: =SUM($D27/12) -> -5000 | ... BL27: =SUM($D27/12) -> -5000
C28: Cloud Engineer 2 | D28: -60000 | Q28: =SUM($D28/12) -> -5000 | R28: =SUM($D28/12) -> -5000 | S28: =SUM($D28/12) -> -5000 | T28: =SUM($D28/12) -> -5000 | U28: =SUM($D28/12) -> -5000 | V28: =SUM($D28/12) -> -5000 | W28: =SUM($D28/12) -> -5000 | X28: =SUM($D28/12) -> -5000 | ... BL28: =SUM($D28/12) -> -5000
C29: Experience Designer 1 | D29: -60000 | K29: =SUM($D28/12) -> -5000 | L29: =SUM($D28/12) -> -5000 | M29: =SUM($D28/12) -> -5000 | N29: =SUM($D28/12) -> -5000 | O29: =SUM($D28/12) -> -5000 | P29: =SUM($D28/12) -> -5000 | Q29: =SUM($D29/12) -> -5000 | R29: =SUM($D29/12) -> -5000 | S29: =SUM($D29/12) -> -5000 | T29: =SUM($D29/12) -> -5000 | U29: =SUM($D29/12) -> -5000 | V29: =SUM($D29/12) -> -5000 | W29: =SUM($D29/12) -> -5000 | X29: =SUM($D29/12) -> -5000 | ... BL29: =SUM($D29/12) -> -5000
C30: Data Scientist 1 | D30: -120000 | Q30: =SUM($D30/12) -> -10000 | R30: =SUM($D30/12) -> -10000 | S30: =SUM($D30/12) -> -10000 | T30: =SUM($D30/12) -> -10000 | U30: =SUM($D30/12) -> -10000 | V30: =SUM($D30/12) -> -10000 | W30: =SUM($D30/12) -> -10000 | X30: =SUM($D30/12) -> -10000 | ... BL30: =SUM($D30/12) -> -10000
C31: Customer Support 1 | D31: -30000 | Q31: =SUM($D31/12) -> -2500 | R31: =SUM($D31/12) -> -2500 | S31: =SUM($D31/12) -> -2500 | T31: =SUM($D31/12) -> -2500 | U31: =SUM($D31/12) -> -2500 | V31: =SUM($D31/12) -> -2500 | W31: =SUM($D31/12) -> -2500 | X31: =SUM($D31/12) -> -2500 | ... BL31: =SUM($D31/12) -> -2500
C32: VR Dev 5 | D32: -60000 | AC32: =SUM($D32/12) -> -5000 | AD32: =SUM($D32/12) -> -5000 | AE32: =SUM($D32/12) -> -5000 | AF32: =SUM($D32/12) -> -5000 | AG32: =SUM($D32/12) -> -5000 | AH32: =SUM($D32/12) -> -5000 | AI32: =SUM($D32/12) -> -5000 | AJ32: =SUM($D32/12) -> -5000 | ... BL32: =SUM($D32/12) -> -5000
C33: VR Dev 6 | D33: -60000 | AC33: =SUM($D33/12) -> -5000 | AD33: =SUM($D33/12) -> -5000 | AE33: =SUM($D33/12) -> -5000 | AF33: =SUM($D33/12) -> -5000 | AG33: =SUM($D33/12) -> -5000 | AH33: =SUM($D33/12) -> -5000 | AI33: =SUM($D33/12) -> -5000 | AJ33: =SUM($D33/12) -> -5000 | ... BL33: =SUM($D33/12) -> -5000
C34: VR Dev 7 | D34: -60000 | AC34: =SUM($D34/12) -> -5000 | AD34: =SUM($D34/12) -> -5000 | AE34: =SUM($D34/12) -> -5000 | AF34: =SUM($D34/12) -> -5000 | AG34: =SUM($D34/12) -> -5000 | AH34: =SUM($D34/12) -> -5000 | AI34: =SUM($D34/12) -> -5000 | AJ34: =SUM($D34/12) -> -5000 | ... BL34: =SUM($D34/12) -> -5000
C35: VR Dev 8 | D35: -60000 | AC35: =SUM($D35/12) -> -5000 | AD35: =SUM($D35/12) -> -5000 | AE35: =SUM($D35/12) -> -5000 | AF35: =SUM($D35/12) -> -5000 | AG35: =SUM($D35/12) -> -5000 | AH35: =SUM($D35/12) -> -5000 | AI35: =SUM($D35/12) -> -5000 | AJ35: =SUM($D35/12) -> -5000 | ... BL35: =SUM($D35/12) -> -5000
C36: Cloud Engineer 3 | D36: -60000 | AC36: =SUM($D36/12) -> -5000 | AD36: =SUM($D36/12) -> -5000 | AE36: =SUM($D36/12) -> -5000 | AF36: =SUM($D36/12) -> -5000 | AG36: =SUM($D36/12) -> -5000 | AH36: =SUM($D36/12) -> -5000 | AI36: =SUM($D36/12) -> -5000 | AJ36: =SUM($D36/12) -> -5000 | ... BL36: =SUM($D36/12) -> -5000
C37: Cloud Engineer 4 | D37: -60000 | AC37: =SUM($D37/12) -> -5000 | AD37: =SUM($D37/12) -> -5000 | AE37: =SUM($D37/12) -> -5000 | AF37: =SUM($D37/12) -> -5000 | AG37: =SUM($D37/12) -> -5000 | AH37: =SUM($D37/12) -> -5000 | AI37: =SUM($D37/12) -> -5000 | AJ37: =SUM($D37/12) -> -5000 | ... BL37: =SUM($D37/12) -> -5000
C38: Experience Designer 2 | D38: -60000 | AC38: =SUM($D38/12) -> -5000 | AD38: =SUM($D38/12) -> -5000 | AE38: =SUM($D38/12) -> -5000 | AF38: =SUM($D38/12) -> -5000 | AG38: =SUM($D38/12) -> -5000 | AH38: =SUM($D38/12) -> -5000 | AI38: =SUM($D38/12) -> -5000 | AJ38: =SUM($D38/12) -> -5000 | ... BL38: =SUM($D38/12) -> -5000
C39: Data Scientist 2 | D39: -120000 | AC39: =SUM($D39/12) -> -10000 | AD39: =SUM($D39/12) -> -10000 | AE39: =SUM($D39/12) -> -10000 | AF39: =SUM($D39/12) -> -10000 | AG39: =SUM($D39/12) -> -10000 | AH39: =SUM($D39/12) -> -10000 | AI39: =SUM($D39/12) -> -10000 | AJ39: =SUM($D39/12) -> -10000 | ... BL39: =SUM($D39/12) -> -10000
C40: Customer Support 2 | D40: -30000 | AC40: =SUM($D40/12) -> -2500 | AD40: =SUM($D40/12) -> -2500 | AE40: =SUM($D40/12) -> -2500 | AF40: =SUM($D40/12) -> -2500 | AG40: =SUM($D40/12) -> -2500 | AH40: =SUM($D40/12) -> -2500 | AI40: =SUM($D40/12) -> -2500 | AJ40: =SUM($D40/12) -> -2500 | ... BL40: =SUM($D40/12) -> -2500
C41: VR Dev 9 | D41: -60000 | AO41: =SUM($D41/12) -> -5000 | AP41: =SUM($D41/12) -> -5000 | AQ41: =SUM($D41/12) -> -5000 | AR41: =SUM($D41/12) -> -5000 | AS41: =SUM($D41/12) -> -5000 | AT41: =SUM($D41/12) -> -5000 | AU41: =SUM($D41/12) -> -5000 | AV41: =SUM($D41/12) -> -5000 | ... BL41: =SUM($D41/12) -> -5000
C42: VR Dev 10 | D42: -60000 | AO42: =SUM($D42/12) -> -5000 | AP42: =SUM($D42/12) -> -5000 | AQ42: =SUM($D42/12) -> -5000 | AR42: =SUM($D42/12) -> -5000 | AS42: =SUM($D42/12) -> -5000 | AT42: =SUM($D42/12) -> -5000 | AU42: =SUM($D42/12) -> -5000 | AV42: =SUM($D42/12) -> -5000 | ... BL42: =SUM($D42/12) -> -5000
C43: Machine Learning Dev 1 | D43: -120000 | AO43: =SUM($D43/12) -> -10000 | AP43: =SUM($D43/12) -> -10000 | AQ43: =SUM($D43/12) -> -10000 | AR43: =SUM($D43/12) -> -10000 | AS43: =SUM($D43/12) -> -10000 | AT43: =SUM($D43/12) -> -10000 | AU43: =SUM($D43/12) -> -10000 | AV43: =SUM($D43/12) -> -10000 | ... BL43: =SUM($D43/12) -> -10000
C44: Machine Learning Dev 2 | D44: -120000 | AO44: =SUM($D44/12) -> -10000 | AP44: =SUM($D44/12) -> -10000 | AQ44: =SUM($D44/12) -> -10000 | AR44: =SUM($D44/12) -> -10000 | AS44: =SUM($D44/12) -> -10000 | AT44: =SUM($D44/12) -> -10000 | AU44: =SUM($D44/12) -> -10000 | AV44: =SUM($D44/12) -> -10000 | ... BL44: =SUM($D44/12) -> -10000
C45: Cloud Engineer 5 | D45: -120000 | AO45: =SUM($D45/12) -> -10000 | AP45: =SUM($D45/12) -> -10000 | AQ45: =SUM($D45/12) -> -10000 | AR45: =SUM($D45/12) -> -10000 | AS45: =SUM($D45/12) -> -10000 | AT45: =SUM($D45/12) -> -10000 | AU45: =SUM($D45/12) -> -10000 | AV45: =SUM($D45/12) -> -10000 | ... BL45: =SUM($D45/12) -> -10000
C46: Cloud Engineer 6 | D46: -120000 | AO46: =SUM($D46/12) -> -10000 | AP46: =SUM($D46/12) -> -10000 | AQ46: =SUM($D46/12) -> -10000 | AR46: =SUM($D46/12) -> -10000 | AS46: =SUM($D46/12) -> -10000 | AT46: =SUM($D46/12) -> -10000 | AU46: =SUM($D46/12) -> -10000 | AV46: =SUM($D46/12) -> -10000 | ... BL46: =SUM($D46/12) -> -10000
C47: Experience Designer 3 | D47: -60000 | AO47: =SUM($D47/12) -> -5000 | AP47: =SUM($D47/12) -> -5000 | AQ47: =SUM($D47/12) -> -5000 | AR47: =SUM($D47/12) -> -5000 | AS47: =SUM($D47/12) -> -5000 | AT47: =SUM($D47/12) -> -5000 | AU47: =SUM($D47/12) -> -5000 | AV47: =SUM($D47/12) -> -5000 | ... BL47: =SUM($D47/12) -> -5000
C48: Data Scientist 3 | D48: -120000 | AO48: =SUM($D48/12) -> -10000 | AP48: =SUM($D48/12) -> -10000 | AQ48: =SUM($D48/12) -> -10000 | AR48: =SUM($D48/12) -> -10000 | AS48: =SUM($D48/12) -> -10000 | AT48: =SUM($D48/12) -> -10000 | AU48: =SUM($D48/12) -> -10000 | AV48: =SUM($D48/12) -> -10000 | ... BL48: =SUM($D48/12) -> -10000
...

Sheet Personnel Plan
H2: VReeMind Personnel Plan
A3: Personnel | B3: 2021 | C3: =B3+1 -> 2022 | D3: =C3+1 -> 2023 | E3: =D3+1 -> 2024 | F3: =E3+1 -> 2025 | H3: Personnel | I3: 2021 | J3: =I3+1 -> 2022 | K3: =J3+1 -> 2023 | L3: =K3+1 -> 2024 | M3: =L3+1 -> 2025
A4: Laurens Coeveld | B4: =SUM(Costs!E19:P19) -> -38000 | C4: =SUM(Costs!Q19:AB19) -> -52250 | D4: =SUM(Costs!AC19:AN19) -> -95000 | E4: =SUM(Costs!AO19:AZ19) -> -152000 | F4: =SUM(Costs!BA19:BL19) -> -190000 | H4: Laurens Coeveld | I4: =ABS(B4) -> 38000 | J4: =ABS(C4) -> 52250 | K4: =ABS(D4) -> 95000 | L4: =ABS(E4) -> 152000 | M4: =ABS(F4) -> 190000
A5: Aaron Smiles | B5: =SUM(Costs!E20:P20) -> -35000 | C5: =SUM(Costs!Q20:AB20) -> -48125 | D5: =SUM(Costs!AC20:AN20) -> -87500 | E5: =SUM(Costs!AO20:AZ20) -> -140000 | F5: =SUM(Costs!BA20:BL20) -> -175000 | H5: Aaron Smiles | I5: =ABS(B5) -> 35000 | J5: =ABS(C5) -> 48125 | K5: =ABS(D5) -> 87500 | L5: =ABS(E5) -> 140000 | M5: =ABS(F5) -> 175000
A6: Scott McFaddin | B6: =SUM(Costs!E21:P21) -> -32000 | C6: =SUM(Costs!Q21:AB21) -> -44000 | D6: =SUM(Costs!AC21:AN21) -> -80000 | E6: =SUM(Costs!AO21:AZ21) -> -128000 | F6: =SUM(Costs!BA21:BL21) -> -160000 | H6: Scott McFaddin | I6: =ABS(B6) -> 32000 | J6: =ABS(C6) -> 44000 | K6: =ABS(D6) -> 80000 | L6: =ABS(E6) -> 128000 | M6: =ABS(F6) -> 160000
A7: Sam Contractor | B7: =SUM(Costs!E22:P22) -> -34000 | C7: =SUM(Costs!Q22:AB22) -> -46750 | D7: =SUM(Costs!AC22:AN22) -> -85000 | E7: =SUM(Costs!AO22:AZ22) -> -136000 | F7: =SUM(Costs!BA22:BL22) -> -170000 | H7: Sam Contractor | I7: =ABS(B7) -> 34000 | J7: =ABS(C7) -> 46750 | K7: =ABS(D7) -> 85000 | L7: =ABS(E7) -> 136000 | M7: =ABS(F7) -> 170000
A8: Other | B8: =SUM(Costs!E23:P57) -> -135000 | C8: =SUM(Costs!Q23:AB57) -> -570000 | D8: =SUM(Costs!AC23:AN57) -> -1140000 | E8: =SUM(Costs!AO23:AZ57) -> -1950000 | F8: =SUM(Costs!BA23:BL57) -> -2730000 | H8: Other | I8: =ABS(B8) -> 135000 | J8: =ABS(C8) -> 570000 | K8: =ABS(D8) -> 1140000 | L8: =ABS(E8) -> 1950000 | M8: =ABS(F8) -> 2730000
A9: Total People | B9: =COUNT(Costs!P19:P58) -> 8 | C9: =COUNT(Costs!AB19:AB58) -> 13 | D9: =COUNT(Costs!AN19:AN58) -> 22 | E9: =COUNT(Costs!AZ19:AZ58) -> 31 | F9: =COUNT(Costs!BL19:BL58) -> 40 | H9: Total People | I9: =ABS(B9) -> 8 | J9: =ABS(C9) -> 13 | K9: =ABS(D9) -> 22 | L9: =ABS(E9) -> 31 | M9: =ABS(F9) -> 40
A10: Total Payroll | B10: =SUM(B4:B8) -> -274000 | C10: =SUM(C4:C8) -> -761125 | D10: =SUM(D4:D8) -> -1487500 | E10: =SUM(E4:E8) -> -2506000 | F10: =SUM(F4:F8) -> -3425000 | H10: Total Payroll | I10: =ABS(B10) -> 274000 | J10: =ABS(C10) -> 761125 | K10: =ABS(D10) -> 1487500 | L10: =ABS(E10) -> 2506000 | M10: =ABS(F10) -> 3425000

Sheet Rev Forecast
E1: Year | F1: 2021 | R1: =F1+1 -> 2022 | AD1: =R1+1 -> 2023 | AP1: =AD1+1 -> 2024 | BB1: =AP1+1 -> 2025
E2: Month | F2: 1 | G2: =F2+1 -> 2 | H2: =G2+1 -> 3 | I2: =H2+1 -> 4 | J2: =I2+1 -> 5 | K2: =J2+1 -> 6 | L2: =K2+1 -> 7 | M2: =L2+1 -> 8 | N2: =M2+1 -> 9 | ... BM2: =BL2+1 -> 60
E4: TOTAL COSTS | F4: =Costs!E4 -> -95867.656 | G4: =Costs!F4 -> -47427.656 | H4: =Costs!G4 -> -50977.656 | I4: =Costs!H4 -> -60646.573 | J4: =Costs!I4 -> -71546.573 | K4: =Costs!J4 -> -59421.573 | L4: =Costs!K4 -> -97494.025 | M4: =Costs!L4 -> -80749.025 | ... BM4: =Costs!BL4 -> -770122.71
B6: Weight (%) | C6: Type | D6: Subscription | E6: Price
C7: Monthly | D7: Silver | E7: 9.99 | F7: =SUM(F8*$E$7) -> 0 | G7: =SUM(G8*$E$7) -> 0 | H7: =SUM(H8*$E$7) -> 0 | I7: =SUM(I8*$E$7) -> 0 | J7: =SUM(J8*$E$7) -> 0 | K7: =SUM(K8*$E$7) -> 0 | L7: =SUM(L8*$E$7) -> 74925 | M7: =SUM(M8*$E$7) -> 78671.25 | ... BM7: =SUM(BM8*$E$7) -> 13387555
A8: # of paid subcribers | B8: 0.15 | L8: =SUM(L15*$B$8) -> 7500 | M8: =L8+(L8*0.05) -> 7875 | N8: =M8+(M8*0.05) -> 8268.75 | O8: =N8+(N8*0.05) -> 8682.1875 | P8: =O8+(O8*0.05) -> 9116.2969 | Q8: =P8+(P8*0.05) -> 9572.1117 | R8: =SUM(R15*$B$8) -> 15000 | S8: =R8+(R8*0.05) -> 15750 | T8: =S8+(S8*0.05) -> 16537.5 | U8: =T8+(T8*0.05) -> 17364.375 | V8: =U8+(U8*0.05) -> 18232.594 | W8: =V8+(V8*0.05) -> 19144.223 | X8: =SUM(X15*$B$8) -> 37500 | Y8: =X8+(X8*0.05) -> 39375 | Z8: =Y8+(Y8*0.05) -> 41343.75 | AA8: =Z8+(Z8*0.05) -> 43410.938 | AB8: =AA8+(AA8*0.05) -> 45581.484 | AC8: =AB8+(AB8*0.05) -> 47860.559 | AD8: =SUM(AD15*$B$8) -> 75000 | AE8: =AD8+(AD8*0.05) -> 78750 | AF8: =AE8+(AE8*0.05) -> 82687.5 | AG8: =AF8+(AF8*0.05) -> 86821.875 | AH8: =AG8+(AG8*0.05) -> 91162.969 | AI8: =AH8+(AH8*0.05) -> 95721.117 | AJ8: =SUM(AJ15*$B$8) -> 150000 | AK8: =AJ8+(AJ8*0.05) -> 157500 | AL8: =AK8+(AK8*0.05) -> 165375 | AM8: =AL8+(AL8*0.05) -> 173643.75 | AN8: =AM8+(AM8*0.05) -> 182325.94 | AO8: =AN8+(AN8*0.05) -> 191442.23 | AP8: =SUM(AP15*$B$8) -> 300000 | AQ8: =AP8+(AP8*0.05) -> 315000 | AR8: =AQ8+(AQ8*0.05) -> 330750 | AS8: =SUM(AS15*$B$8) -> 375000 | AT8: =AS8+(AS8*0.05) -> 393750 | AU8: =AT8+(AT8*0.05) -> 413437.5 | AV8: =SUM(AV15*$B$8) -> 450000 | AW8: =AV8+(AV8*0.05) -> 472500 | AX8: =AW8+(AW8*0.05) -> 496125 | AY8: =SUM(AY15*$B$8) -> 525000 | AZ8: =AY8+(AY8*0.05) -> 551250 | BA8: =AZ8+(AZ8*0.05) -> 578812.5 | BB8: =SUM(BB15*$B$8) -> 675000 | BC8: =BB8+(BB8*0.05) -> 708750 | BD8: =BC8+(BC8*0.05) -> 744187.5 | BE8: =SUM(BE15*$B$8) -> 750000 | BF8: =BE8+(BE8*0.05) -> 787500 | BG8: =BF8+(BF8*0.05) -> 826875 | BH8: =SUM(BH15*$B$8) -> 1050000 | BI8: =BH8+(BH8*0.05) -> 1102500 | BJ8: =BI8+(BI8*0.05) -> 1157625 | BK8: =BJ8+(BJ8*0.05) -> 1215506.2 | BL8: =BK8+(BK8*0.05) -> 1276281.6 | BM8: =BL8+(BL8*0.05) -> 1340095.6
C9: Monthly | D9: Gold | E9: 19.99 | F9: =SUM(F10*$E$9) -> 0 | G9: =SUM(G10*$E$9) -> 0 | H9: =SUM(H10*$E$9) -> 0 | I9: =SUM(I10*$E$9) -> 0 | J9: =SUM(J10*$E$9) -> 0 | K9: =SUM(K10*$E$9) -> 0 | L9: =SUM(L10*$E$9) -> 799600 | M9: =SUM(M10*$E$9) -> 839580 | ... BM9: =SUM(BM10*$E$9) -> 1.4287206e+08
