Workbook
Name Gross_margin: 'Break-Even'!$G$19
Name Sales_price_unit: 'Break-Even'!$F$5
Name Sales_volume_units: 'Break-Even'!$F$6
Name SalesCycle: Projections!$C$117
Name Total_fixed: 'Break-Even'!$G$29
Name Total_Sales: 'Break-Even'!$G$7
Name Total_variable: 'Break-Even'!$G$16
Name Unit_contrib_margin: 'Break-Even'!$F$18
Name Variable_costs_unit: 'Break-Even'!$F$10:$F$11
Name Variable_Unit_Cost: 'Break-Even'!$F$15

Sheet Welcome
F4: Subscription Financial Model Template
F5: version 2.04
G7: To Edit in Google Sheets Go to File > Make a Copy | J7: To Edit in Excel Go to File > Download
B10: Legal Disclaimer | F10: Help & Resources | M10: More Templates
B12: This document is provided as a reference and template, and the financial information included should not be considered an certified business valuation, or projection. The information provided by Slidebean Incorporated (“we,” “us” or “our”) on https://slidebean.com (the “Site”) is for general informational purposes only. All information on the Site is provided in good faith, however we make no representation or warranty of any kind, express or implied, regarding the accuracy, adequacy, validity, reliability, availability or completeness of any information on the Site. UNDER NO CIRCUMSTANCE SHALL WE HAVE ANY LIABILITY TO YOU FOR ANY LOSS OR DAMAGE OF ANY KIND INCURRED AS A RESULT OF THE USE OF THE SITE OR RELIANCE ON ANY INFORMATION PROVIDED ON THE SITE. YOUR USE OF THE SITE AND YOUR RELIANCE ON ANY INFORMATION ON THE SITE IS SOLELY AT YOUR OWN RISK. The Site cannot and does not contain financial advice. The financial information is provided for general informational and educational purposes only and is not a substitute for professional advice. Accordingly, before taking any actions based upon such information, we encourage you to consult with the appropriate professionals. We do not provide any kind of financial advice. THE USE OR RELIANCE OF ANY INFORMATION CONTAINED ON THIS SITE IS SOLELY AT YOUR OWN RISK. | F12: =HYPERLINK("https://www.youtube.com/watch?v=rwUxqjnksAc","Watch the Tutorial") -> Watch the Tutorial | M12: =HYPERLINK("https://slidebean.com/pitch-deck-template","Pitch Deck Template for Startups") -> Pitch Deck Template for Startups
F14: =HYPERLINK("https://calendly.com/slidebean-strategy-team/financial-model","Book a Call with our Experts") -> Book a Call with our Experts | M14: =HYPERLINK("https://checkout.slidebean.com/product/financial-model-template-saas","Subscription Business Financial Model") -> Subscription Business Financial Model
F15: Book a call with our financial modeling experts. They can walk you through specific questions in our formulas, or help you customize the model to your business.
M16: =HYPERLINK("https://checkout.slidebean.com/product/financial-model-template-ecommerce","eCommerce Platform Financial Model") -> eCommerce Platform Financial Model
F17: =HYPERLINK("https://slidebean.com/youtube#discord","Get Help from the Community") -> Get Help from the Community
F18: Join our Discord community and get your questions answered by fellow startup founders. | M18: =HYPERLINK("https://checkout.slidebean.com/product/marketplace-financial-model","Marketplace Financial Model") -> Marketplace Financial Model
F20: =HYPERLINK("https://app.hubspot.com/meetings/derek54/fin-model-call","Get a Custom Financial Model") -> Get a Custom Financial Model | M20: =HYPERLINK("https://checkout.slidebean.com/product/social-media-platform-financial-model-template","Social Media Platform Financial Model") -> Social Media Platform Financial Model
F21: Our team can build a custom financial model for your based on your specific business requirements. This service starts at $649.
M22: =HYPERLINK("https://checkout.slidebean.com/product/blog-news-site-financial-model-template","Blog/News Site Financial Model") -> Blog/News Site Financial Model

Sheet Change Log
B3: The Ultimate Financial Model for Startups | H3: 2.01 | I3: Fixed an issue with Organic Traffic driving paid customers revenue models not yet enabled. Revenue rows 63 and 122.
I4: Fixed the count of total active customers (Revenue row 37). It cause the support agents needed to be 0.
I5: Added Freeze Row/Column to some sheets that didn't have it.
B7: version 2.04 | H7: 2.02 | I7: New welcome page Removed hidden 'Slides' sheet
H9: 2.03 | I9: Fixed an issue with the Teams & Salaries formula that caused errors on the quarterly and annually hiring cycles
I10: Fixed formula error on SG&A row 77
I11: Changed the design of this (Change Log) Sheet
H13: 2.031 | I13: Fixed Revenue Rows 15/16 - Total Sales Team Budget and Total Marketing Budget was sourcing the wrong column from SG&A.
H14: 2.032 | I14: Fixed issue with Monthly Billing MRR not being reported. Revenue rows 105, 169 and 220.
H15: 2.033 | I15: Fixed issue with Inbound sales agents not being added to the Headcount.
I16: Removed VP of Sales as an option for Inbound Sales scaling
I17: Customer count was not including annual subscribers.
H19: 2.034 | I19: Formatting changes in the Revenue sheet
I20: Added SaaS Quick Ratio
I21: Fixed an error on the Outbound Sales delay for 2 months
H23: 2.04 | I23: Fixed an issue with the Marketing Team salaries not being referenced correctly.
I24: Fixed an issue with the annual salary increase referring the CEO cell.
I25: FS-Month Row 44 (D&A) was refererencing an incorrect cell in CAPEX.
I26: Typo on FS Rows 109 and 115
I27: Valuation Section on FS-Month was missing references.
I28: Fixed formatting issue in CAPEX Sheet
I29: Fixed typos and reference errors in Revenue KPIs

Sheet Intro
A1: =Settings!C5 -> VReeMind
A2: Financial Model Guide
A3: =+TODAY() -> 44143
A9: COLOR CODING
A11: Inputs/assumptions | B11: BLUE | C11: Inputs, or any hard-coded data, such as historical values, assumptions, and drivers.
A12: Formulas/results | B12: BLACK | C12: Formulas, calculations, or references deriving from inputs
A15: CONTENTS
A18: Settings | C18: General settings
A19: Salaries | C19: A summary of salaries and team members
A20: Projections | C20: Use this sheet to summarize the variables that directly affect the business projections
A21: Charts & KPIs | C21: A summary of P&L charts, capital requirements and other KPIs relevant to the business
A22: CapTable | C22: Capitalization table including estimated Round A clossing
A23: FS-Annual | C23: Projected annual financial statements
A24: FS-Month | C24: Projected monthly financial statements
A25: Revenue | C25: Detailed monthly revenue assumptions & projections
A26: COGS | C26: Detailed monthly cost of goods sold (COGS) assumptions & projections
A27: SG&A | C27: Detailed monthly selling, general & administrative expenses (SG&A) assumptions & projections
A28: WK+CAPEX | C28: Detailed monthly working capital (WK) & capital expenditures (CAPEX) assumptions & projections
A29: Funding - Equity Round Estimation | C29: A simple calculator to estimate the stock that needs to be issued on a (priced) round of funding
A30: Funding - Convertible Note Estimation | C30: A simple calculator to estimate the stock that needs to be issued on a convertible note funding round

Sheet Settings
A1: Item | B1: Format | C1: Input | D1: Notes
A4: GENERAL
A5: Company Name | C5: VReeMind
A6: Currency | C6: USD
A7: Model Start Date | C7: 43466
A10: FS-MONTH
A11: Initial Cash Balance | B11: =Settings!$C$6 -> USD | C11: 50000
A13: FS-ANNUAL
A15: Taxes & Inflation
A16: Income tax rate | B16: % | C16: 0 | D16: Will be used to estimate the the annual tax payment, that will be added to FS-Month
A17: Inflation | B17: % | C17: 0.03 | D17: Used for buiness valuation calculations
A19: Valuation
A20: Business terminal value | C20: xEBITDA | D20: This model will estimate your current business valuation based on a Discounted Cash Flow Model:
A21: Discount rate - Today | B21: % | C21: 0.15 | D21: https://www.investopedia.com/terms/d/dcf.asp#:~:text=Discounted%20cash%20flow%20(DCF)%20is,will%20generate%20in%20the%20future.
A22: xEBITDA | B22: Multiplier | C22: 10
A23: Debt/Capital Ratio | B23: % | C23: 0.05
A24: Debt interest rate | B24: % | C24: 0.1
A26: CAPEX
A28: OPERATING CASH
A29: Balance | B29: =Settings!$C$6 -> USD | C29: 0
A30: Percentage of revenues | B30: % | C30: 0.1
A32: Accounts Receivable
A33: Pending Income/Total Income | B33: % | C33: 0
A35: Pre-paid expenses
A36: Pre-paid Days Outstanding | B36: days | C36: 30
A38: Accounts Payable
A39: A/P as % of total COGS | B39: % | C39: 0
A41: CAPITAL EXPENDITURES
A42: Automatically estimate new computer purchases for new employees | B42: Dropdown | C42: YES
A43: Price per computer | B43: =$C$6 -> USD | C43: 1000
A45: TIME FOR ASSETS TO DEPRECIATE
A46: Apartment/office fixings | B46: Years | C46: 10
A47: Office furniture | B47: Years | C47: 5
A48: Computers | B48: Years | C48: 3
A49: Telecom equipment | B49: Years | C49: 5
A50: Servers & other tech infrastructure | B50: Years | C50: 5
A51: Other | B51: Years | C51: 5

Sheet Team & Salaries
A1: Salaries | B1: Expense Category | C1: Currency | D1: Monthly Cost to Company | E1: Monthly Salary | F1: Year 2 | G1: Year 3 | H1: Year 4 | I1: Year 5 | J1: Year 6 | K1: Annual Salary | L1: Payroll Taxes + Benefits | M1: First Hire | N1: How many hires added per period? | O1: How often are new hires added? | P1: Maximum Team | Q1: Annual Increase | R1: Notes
A2: If you need additional roles, just unhide rows. | N2: Set to 0 if you would like to disable the position
A5: Operations
A6: CEO | B6: Ops | C6: USD | D6: =E6*(1+L6) -> 2291.6667 | E6: =K6/12 -> 2083.3333 | F6: =D6*(1+$Q6) -> 2360.4167 | G6: =F6*(1+$Q6) -> 2431.2292 | H6: =G6*(1+$Q6) -> 2504.166 | I6: =H6*(1+$Q6) -> 2579.291 | J6: =I6*(1+$Q6) -> 2656.6698 | K6: 25000 | L6: 0.1 | M6: 43466 | N6: =IF(M6>0,1,0) -> 1 | O6: Never | P6: 1 | Q6: 0.03
A7: UX Research | B7: Ops | C7: USD | D7: =E7*(1+L7) -> 2291.6667 | E7: =K7/12 -> 2083.3333 | F7: =D7*(1+$Q7) -> 2360.4167 | G7: =F7*(1+$Q7) -> 2431.2292 | H7: =G7*(1+$Q7) -> 2504.166 | I7: =H7*(1+$Q7) -> 2579.291 | J7: =I7*(1+$Q7) -> 2656.6698 | K7: 25000 | L7: 0.1 | M7: 43466 | N7: =IF(M7>0,1,0) -> 1 | O7: Never | P7: 1 | Q7: 0.03
A8: CFO | B8: Ops | C8: USD | D8: =E8*(1+L8) -> 2291.6667 | E8: =K8/12 -> 2083.3333 | F8: =D8*(1+$Q8) -> 2360.4167 | G8: =F8*(1+$Q8) -> 2431.2292 | H8: =G8*(1+$Q8) -> 2504.166 | I8: =H8*(1+$Q8) -> 2579.291 | J8: =I8*(1+$Q8) -> 2656.6698 | K8: 25000 | L8: 0.1 | M8: 44197 | N8: =IF(M8>0,1,0) -> 1 | O8: Never | P8: 1 | Q8: 0.03
A9: Intern | B9: Ops | C9: USD | D9: =E9*(1+L9) -> 2291.6667 | E9: =K9/12 -> 2083.3333 | F9: =D9*(1+$Q9) -> 2360.4167 | G9: =F9*(1+$Q9) -> 2431.2292 | H9: =G9*(1+$Q9) -> 2504.166 | I9: =H9*(1+$Q9) -> 2579.291 | J9: =I9*(1+$Q9) -> 2656.6698 | K9: 25000 | L9: 0.1 | M9: 44197 | N9: =IF(M9>0,1,0) -> 1 | O9: Never | P9: 1 | Q9: 0.03
A10: CEO 2 | B10: Ops | C10: USD | D10: =E10*(1+L10) -> 4583.3333 | E10: =K10/12 -> 4166.6667 | F10: =D10*(1+$Q10) -> 4812.5 | G10: =F10*(1+$Q10) -> 5053.125 | H10: =G10*(1+$Q10) -> 5305.7813 | I10: =H10*(1+$Q10) -> 5571.0703 | J10: =I10*(1+$Q10) -> 5849.6238 | K10: 50000 | L10: 0.1 | M10: 44562 | N10: =IF(M10>0,1,0) -> 1 | O10: Never | P10: 1 | Q10: 0.05
A11: CFO 2 | B11: Ops | C11: USD | D11: =E11*(1+L11) -> 4583.3333 | E11: =K11/12 -> 4166.6667 | F11: =D11*(1+$Q11) -> 4812.5 | G11: =F11*(1+$Q11) -> 5053.125 | H11: =G11*(1+$Q11) -> 5305.7813 | I11: =H11*(1+$Q11) -> 5571.0703 | J11: =I11*(1+$Q11) -> 5849.6238 | K11: 50000 | L11: 0.1 | M11: 44562 | N11: =IF(M11>0,1,0) -> 1 | O11: Never | P11: 1 | Q11: 0.05
A12: CTO 2 | B12: Ops | C12: USD | D12: =E12*(1+L12) -> 4583.3333 | E12: =K12/12 -> 4166.6667 | F12: =D12*(1+$Q12) -> 4812.5 | G12: =F12*(1+$Q12) -> 5053.125 | H12: =G12*(1+$Q12) -> 5305.7813 | I12: =H12*(1+$Q12) -> 5571.0703 | J12: =I12*(1+$Q12) -> 5849.6238 | K12: 50000 | L12: 0.1 | M12: 44562 | N12: =IF(M12>0,1,0) -> 1 | O12: Never | P12: 1 | Q12: 0.05
A13: CMO 2 | B13: Ops | C13: USD | D13: =E13*(1+L13) -> 4583.3333 | E13: =K13/12 -> 4166.6667 | F13: =D13*(1+$Q13) -> 4812.5 | G13: =F13*(1+$Q13) -> 5053.125 | H13: =G13*(1+$Q13) -> 5305.7813 | I13: =H13*(1+$Q13) -> 5571.0703 | J13: =I13*(1+$Q13) -> 5849.6238 | K13: 50000 | L13: 0.1 | M13: 44562 | N13: =IF(M13>0,1,0) -> 1 | O13: Never | P13: 1 | Q13: 0.05
Q14: 0.03
Q15: 0.03
A16: Product | Q16: 0.03
A17: CTO | B17: Prod | C17: USD | D17: =E17*(1+L17) -> 2291.6667 | E17: =K17/12 -> 2083.3333 | F17: =D17*(1+$Q17) -> 2360.4167 | G17: =F17*(1+$Q17) -> 2431.2292 | H17: =G17*(1+$Q17) -> 2504.166 | I17: =H17*(1+$Q17) -> 2579.291 | J17: =I17*(1+$Q17) -> 2656.6698 | K17: 25000 | L17: 0.1 | M17: 43466 | N17: =IF(M17>0,1,0) -> 1 | O17: Never | P17: =IF(N17=1,1,0) -> 1 | Q17: 0.03
A18: 3D Design | B18: Prod | C18: USD | D18: =E18*(1+L18) -> 2291.6667 | E18: =K18/12 -> 2083.3333 | F18: =D18*(1+$Q18) -> 2360.4167 | G18: =F18*(1+$Q18) -> 2431.2292 | H18: =G18*(1+$Q18) -> 2504.166 | I18: =H18*(1+$Q18) -> 2579.291 | J18: =I18*(1+$Q18) -> 2656.6698 | K18: 25000 | L18: 0.1 | M18: 43647 | N18: =IF(M18>0,1,0) -> 1 | O18: Never | P18: =IF(N18=1,1,0) -> 1 | Q18: 0.03
A19: 3D Design | B19: Prod | C19: USD | D19: =E19*(1+L19) -> 2291.6667 | E19: =K19/12 -> 2083.3333 | F19: =D19*(1+$Q19) -> 2360.4167 | G19: =F19*(1+$Q19) -> 2431.2292 | H19: =G19*(1+$Q19) -> 2504.166 | I19: =H19*(1+$Q19) -> 2579.291 | J19: =I19*(1+$Q19) -> 2656.6698 | K19: 25000 | L19: 0.1 | M19: 44378 | N19: =IF(M19>0,1,0) -> 1 | O19: Never | P19: 1 | Q19: 0.03
A20: 3D Design | B20: Prod | C20: USD | D20: =E20*(1+L20) -> 2291.6667 | E20: =K20/12 -> 2083.3333 | F20: =D20*(1+$Q20) -> 2360.4167 | G20: =F20*(1+$Q20) -> 2431.2292 | H20: =G20*(1+$Q20) -> 2504.166 | I20: =H20*(1+$Q20) -> 2579.291 | J20: =I20*(1+$Q20) -> 2656.6698 | K20: 25000 | L20: 0.1 | M20: 44378 | N20: =IF(M20>0,1,0) -> 1 | O20: Never | P20: 1 | Q20: 0.03
A21: 3D Design | B21: Prod | C21: USD | D21: =E21*(1+L21) -> 6875 | E21: =K21/12 -> 6250 | F21: =D21*(1+$Q21) -> 7081.25 | G21: =F21*(1+$Q21) -> 7293.6875 | H21: =G21*(1+$Q21) -> 7512.4981 | I21: =H21*(1+$Q21) -> 7737.8731 | J21: =I21*(1+$Q21) -> 7970.0093 | K21: 75000 | L21: 0.1 | M21: 45292 | N21: =IF(M21>0,1,0) -> 1 | O21: Never | P21: 1 | Q21: 0.03
A22: 3D Design | B22: Prod | C22: USD | D22: =E22*(1+L22) -> 6875 | E22: =K22/12 -> 6250 | F22: =D22*(1+$Q22) -> 7081.25 | G22: =F22*(1+$Q22) -> 7293.6875 | H22: =G22*(1+$Q22) -> 7512.4981 | I22: =H22*(1+$Q22) -> 7737.8731 | J22: =I22*(1+$Q22) -> 7970.0093 | K22: 75000 | L22: 0.1 | M22: 45292 | N22: =IF(M22>0,1,0) -> 1 | O22: Never | P22: 1 | Q22: 0.03
A23: Mobile Dev | B23: Prod | C23: USD | D23: =E23*(1+L23) -> 6875 | E23: =K23/12 -> 6250 | F23: =D23*(1+$Q23) -> 7081.25 | G23: =F23*(1+$Q23) -> 7293.6875 | H23: =G23*(1+$Q23) -> 7512.4981 | I23: =H23*(1+$Q23) -> 7737.8731 | J23: =I23*(1+$Q23) -> 7970.0093 | K23: 75000 | L23: 0.1 | M23: 44927 | N23: =IF(M23>0,1,0) -> 1 | O23: Never | P23: 1 | Q23: 0.03
A24: Mobile Dev | B24: Prod | C24: USD | D24: =E24*(1+L24) -> 2291.6667 | E24: =K24/12 -> 2083.3333 | F24: =D24*(1+$Q24) -> 2360.4167 | G24: =F24*(1+$Q24) -> 2431.2292 | H24: =G24*(1+$Q24) -> 2504.166 | I24: =H24*(1+$Q24) -> 2579.291 | J24: =I24*(1+$Q24) -> 2656.6698 | K24: 25000 | L24: 0.1 | M24: 43556 | N24: =IF(M24>0,1,0) -> 1 | O24: Never | P24: 1 | Q24: 0.03
A25: Mobile Dev | B25: Prod | C25: USD | D25: =E25*(1+L25) -> 2291.6667 | E25: =K25/12 -> 2083.3333 | F25: =D25*(1+$Q25) -> 2360.4167 | G25: =F25*(1+$Q25) -> 2431.2292 | H25: =G25*(1+$Q25) -> 2504.166 | I25: =H25*(1+$Q25) -> 2579.291 | J25: =I25*(1+$Q25) -> 2656.6698 | K25: 25000 | L25: 0.1 | M25: 43556 | N25: =IF(M25>0,1,0) -> 1 | O25: Never | P25: 1 | Q25: 0.03
A26: Mobile Dev | B26: Prod | C26: USD | D26: =E26*(1+L26) -> 2291.6667 | E26: =K26/12 -> 2083.3333 | F26: =D26*(1+$Q26) -> 2360.4167 | G26: =F26*(1+$Q26) -> 2431.2292 | H26: =G26*(1+$Q26) -> 2504.166 | I26: =H26*(1+$Q26) -> 2579.291 | J26: =I26*(1+$Q26) -> 2656.6698 | K26: 25000 | L26: 0.1 | M26: 44378 | N26: =IF(M26>0,1,0) -> 1 | O26: Never | P26: 1 | Q26: 0.03
A27: Mobile Dev | B27: Prod | C27: USD | D27: =E27*(1+L27) -> 2291.6667 | E27: =K27/12 -> 2083.3333 | F27: =D27*(1+$Q27) -> 2360.4167 | G27: =F27*(1+$Q27) -> 2431.2292 | H27: =G27*(1+$Q27) -> 2504.166 | I27: =H27*(1+$Q27) -> 2579.291 | J27: =I27*(1+$Q27) -> 2656.6698 | K27: 25000 | L27: 0.1 | M27: 44378 | N27: =IF(M27>0,1,0) -> 1 | O27: Never | P27: 1 | Q27: 0.03
A28: Mobile Dev | B28: Prod | C28: USD | D28: =E28*(1+L28) -> 2291.6667 | E28: =K28/12 -> 2083.3333 | F28: =D28*(1+$Q28) -> 2360.4167 | G28: =F28*(1+$Q28) -> 2431.2292 | H28: =G28*(1+$Q28) -> 2504.166 | I28: =H28*(1+$Q28) -> 2579.291 | J28: =I28*(1+$Q28) -> 2656.6698 | K28: 25000 | L28: 0.1 | M28: 44378 | N28: =IF(M28>0,1,0) -> 1 | O28: Never | P28: 1 | Q28: 0.03
A29: Mobile Dev | B29: Prod | C29: USD | D29: =E29*(1+L29) -> 6875 | E29: =K29/12 -> 6250 | F29: =D29*(1+$Q29) -> 7081.25 | G29: =F29*(1+$Q29) -> 7293.6875 | H29: =G29*(1+$Q29) -> 7512.4981 | I29: =H29*(1+$Q29) -> 7737.8731 | J29: =I29*(1+$Q29) -> 7970.0093 | K29: 75000 | L29: 0.1 | M29: 45108 | N29: =IF(M29>0,1,0) -> 1 | O29: Never | P29: 1 | Q29: 0.03
A30: Scrum Master | B30: Prod | C30: USD | D30: =E30*(1+L30) -> 4583.3333 | E30: =K30/12 -> 4166.6667 | F30: =D30*(1+$Q30) -> 4720.8333 | G30: =F30*(1+$Q30) -> 4862.4583 | H30: =G30*(1+$Q30) -> 5008.3321 | I30: =H30*(1+$Q30) -> 5158.582 | J30: =I30*(1+$Q30) -> 5313.3395 | K30: 50000 | L30: 0.1 | M30: 45658 | N30: =IF(M30>0,1,0) -> 1 | O30: Never | P30: 1 | Q30: 0.03
... A42: VR Dev 4 | B42: Prod | C42: USD | D42: =E42*(1+L42) -> 5500 | E42: =K42/12 -> 5000 | F42: =D42*(1+$Q42) -> 5665 | G42: =F42*(1+$Q42) -> 5834.95 | H42: =G42*(1+$Q42) -> 6009.9985 | I42: =H42*(1+$Q42) -> 6190.2985 | J42: =I42*(1+$Q42) -> 6376.0074 | K42: 60000 | L42: 0.1 | M42: 44835 | N42: =IF(M42>0,1,0) -> 1 | O42: Never | P42: 1 | Q42: 0.03
Q43: 0.03
Q44: 0.03
A45: Marketing & Sales | Q45: 0.03
A46: CMO | B46: Growth | C46: USD | D46: =E46*(1+L46) -> 2291.6667 | E46: =K46/12 -> 2083.3333 | F46: =D46*(1+$Q46) -> 2360.4167 | G46: =F46*(1+$Q46) -> 2431.2292 | H46: =G46*(1+$Q46) -> 2504.166 | I46: =H46*(1+$Q46) -> 2579.291 | J46: =I46*(1+$Q46) -> 2656.6698 | K46: 25000 | L46: 0.1 | M46: 44197 | N46: =IF(M46>0,1,0) -> 1 | O46: Never | P46: 1 | Q46: 0.03
A47: Digital Marketer | B47: Growth | C47: USD | D47: =E47*(1+L47) -> 2291.6667 | E47: =K47/12 -> 2083.3333 | F47: =D47*(1+$Q47) -> 2360.4167 | G47: =F47*(1+$Q47) -> 2431.2292 | H47: =G47*(1+$Q47) -> 2504.166 | I47: =H47*(1+$Q47) -> 2579.291 | J47: =I47*(1+$Q47) -> 2656.6698 | K47: 25000 | L47: 0.1 | M47: 44197 | N47: =IF(M47>0,1,0) -> 1 | O47: Never | P47: 1 | Q47: 0.03
A48: Digital Marketer | B48: Growth | C48: USD | D48: =E48*(1+L48) -> 2291.6667 | E48: =K48/12 -> 2083.3333 | F48: =D48*(1+$Q48) -> 2360.4167 | G48: =F48*(1+$Q48) -> 2431.2292 | H48: =G48*(1+$Q48) -> 2504.166 | I48: =H48*(1+$Q48) -> 2579.291 | J48: =I48*(1+$Q48) -> 2656.6698 | K48: 25000 | L48: 0.1 | M48: 44197 | N48: =IF(M48>0,1,0) -> 1 | O48: Never | P48: =IF(N48=1,1,0) -> 1 | Q48: 0.03
A49: Digital Marketer | B49: Growth | C49: USD | D49: =E49*(1+L49) -> 2291.6667 | E49: =K49/12 -> 2083.3333 | F49: =D49*(1+$Q49) -> 2360.4167 | G49: =F49*(1+$Q49) -> 2431.2292 | H49: =G49*(1+$Q49) -> 2504.166 | I49: =H49*(1+$Q49) -> 2579.291 | J49: =I49*(1+$Q49) -> 2656.6698 | K49: 25000 | L49: 0.1 | M49: 44197 | N49: =IF(M49>0,1,0) -> 1 | O49: Never | P49: =IF(N49=1,1,0) -> 1 | Q49: 0.03
A50: Digital Marketer | B50: Growth | C50: USD | D50: =E50*(1+L50) -> 3208.3333 | E50: =K50/12 -> 2916.6667 | F50: =D50*(1+$Q50) -> 3304.5833 | G50: =F50*(1+$Q50) -> 3403.7208 | H50: =G50*(1+$Q50) -> 3505.8325 | I50: =H50*(1+$Q50) -> 3611.0074 | J50: =I50*(1+$Q50) -> 3719.3377 | K50: 35000 | L50: 0.1 | M50: 45292 | N50: =IF(M50>0,1,0) -> 1 | O50: Never | P50: =IF(N50=1,1,0) -> 1 | Q50: 0.03
A51: Sales & Maketing | B51: Growth | C51: USD | D51: =E51*(1+L51) -> 3208.3333 | E51: =K51/12 -> 2916.6667 | F51: =D51*(1+$Q51) -> 3304.5833 | G51: =F51*(1+$Q51) -> 3403.7208 | H51: =G51*(1+$Q51) -> 3505.8325 | I51: =H51*(1+$Q51) -> 3611.0074 | J51: =I51*(1+$Q51) -> 3719.3377 | K51: 35000 | L51: 0.1 | M51: 44562 | N51: =IF(M51>0,1,0) -> 1 | O51: Never | P51: =IF(N51=1,1,0) -> 1 | Q51: 0.03
A52: Sales & Maketing | B52: Growth | C52: USD | D52: =E52*(1+L52) -> 3208.3333 | E52: =K52/12 -> 2916.6667 | F52: =D52*(1+$Q52) -> 3304.5833 | G52: =F52*(1+$Q52) -> 3403.7208 | H52: =G52*(1+$Q52) -> 3505.8325 | I52: =H52*(1+$Q52) -> 3611.0074 | J52: =I52*(1+$Q52) -> 3719.3377 | K52: 35000 | L52: 0.1 | M52: 44562 | N52: =IF(M52>0,1,0) -> 1 | O52: Never | P52: =IF(N52=1,1,0) -> 1 | Q52: 0.03
A53: Sales & Maketing | B53: Growth | C53: USD | D53: =E53*(1+L53) -> 3208.3333 | E53: =K53/12 -> 2916.6667 | F53: =D53*(1+$Q53) -> 3304.5833 | G53: =F53*(1+$Q53) -> 3403.7208 | H53: =G53*(1+$Q53) -> 3505.8325 | I53: =H53*(1+$Q53) -> 3611.0074 | J53: =I53*(1+$Q53) -> 3719.3377 | K53: 35000 | L53: 0.1 | M53: 44927 | N53: =IF(M53>0,1,0) -> 1 | O53: Never | P53: =IF(N53=1,1,0) -> 1 | Q53: 0.03
...

Sheet Projections
A1: Item | B1: Format | C1: Input | D1: Scenario A | E1: Scenario B | F1: Scenario C | G1: Notes
A2: General Settings
A4: Fundraising Close Date | B4: Date | C4: 43739 | D4: 44197 | E4: 44197 | F4: 44197
A5: Investment Amount | B5: =Settings!$C$6 -> USD | C5: 100000 | D5: 0 | E5: 0 | F5: 0
A10: REVENUE
A12: Organic Website Traffic
A13: Use this section to estimate the success of your SEO, Brand Awareness and customer referral efforts. Your total estimated traffic will be visible on the KPI section of the Revenue Sheet.
A14: Organic traffic is disonnected from the budget: that means that you can project organic traffic regardless of how much you are spending. Still, it is recommended to use realistic expectations.
A16: Brand Awareness Budget
A17: Starting Budget | B17: =Settings!$C$6 -> USD | C17: 0 | G17: Expenses automatically added to the SG&A Sheet
A18: Monthly Marketing Budget Increase | B18: =Settings!$C$6 -> USD | C18: 0 | G18: Expenses automatically added to the SG&A Sheet
A19: Maximum Marketing Budget | B19: =Settings!$C$6 -> USD | C19: 0 | G19: Expenses automatically added to the SG&A Sheet
A21: Website Traffic
A22: Organic Traffic Efforts Kick-Off | B22: Date | C22: 44287 | D22: 44197 | E22: 44197 | F22: 44197
A23: Website Traffic at launch | B23: # | C23: 0
A24: Monthly Traffic Increase | B24: % | C24: 0
A25: Maximum Possible Organic Website Traffic | B25: # | C25: 0
A30: SOURCE #1: Self-Service Subscriptions | C30: Enabled
A31: Enable this section if you expect to close deals without a sales team. Your customers go to your website and convert without any sales efforts required.
A32: Customers convert directly from organic or paid traffic, into paid accounts.
A34: Business Model
A35: Expected Launch | B35: Date | C35: 44287 | D35: 44197 | E35: 44197 | F35: 44197
A36: ARPU | B36: =Settings!$C$6 -> USD | C36: 276 | G36: The average account revenue per account, per month. If you have multiple plans, provide an average of the plan price.
A37: How will you primarily bill your customers | B37: =Settings!$C$6 -> USD | C37: Yearly
A38: ="Expected "&C37&" Churn Rate" -> Expected Yearly Churn Rate | B38: % | C38: 0.7 | G38: Most B2C companies try to stay near 5% monthly churn. Most B2B companies aim for 0-2% monthly churn
A39: Expected Lifetime Value | B39: =Settings!$C$6 -> USD | C39: =IF(C37="Monthly",C36/C38,C36/(C38/12)) -> 4731.4286
A41: Organic Traffic
A42: Organic Traffic Conversion to Paid | B42: % | C42: 0.01
A44: Paid Traffic | G44: Use this section to estimate the success of your paid ads (Google Ads, Facebook, etc...)
A45: Paid Traffic Marketing Budget
A46: Starting Marketing Budget | B46: =Settings!$C$6 -> USD | C46: 0 | G46: Expenses automatically added to the SG&A Sheet
A47: Monthly Marketing Budget Increase | B47: =Settings!$C$6 -> USD | C47: 0 | G47: Expenses automatically added to the SG&A Sheet
A48: Maximum Paid Ads Marketing Budget | B48: =Settings!$C$6 -> USD | C48: 0 | G48: Expenses automatically added to the SG&A Sheet
A50: Cost of acqusition
A51: Expected CAC, first month | B51: =Settings!$C$6 -> USD | C51: 15 | G51: Cost of acquisition per account
A52: Monthly CAC change | B52: =Settings!$C$6 -> USD | C52: -2 | G52: Use positive numbers if you assume your CAC will go up. Use negative numbers if you expect it to go down. Most SaaS companies see this number increase as they scale.
A53: Minimum CAC possible | B53: =Settings!$C$6 -> USD | C53: 30 | G53: The minimum possible CAC you expect
A60: SOURCE #2: Inbound Sales | C60: Disabled
A61: Enable this section if you expect to close deals using lead generation, lead nurturing and a team to close sales.
A62: Traffic converts to leads, which are then handled by your sales team.
...

Sheet Data for Charts
A1: =Settings!C5 -> VReeMind
A2: Data for Charts
A3: =+TODAY() -> 44143
D6: ='FS-Month'!D6 -> 43466 | E6: ='FS-Month'!E6 -> 43497 | F6: ='FS-Month'!F6 -> 43525 | G6: ='FS-Month'!G6 -> 43556 | H6: ='FS-Month'!H6 -> 43586 | I6: ='FS-Month'!I6 -> 43617 | J6: ='FS-Month'!J6 -> 43647 | K6: ='FS-Month'!K6 -> 43678 | ... BK6: ='FS-Month'!BK6 -> 45261 | BL6: ='FS-Month'!#REF! -> #REF! | BM6: ='FS-Month'!#REF! -> #REF! | BN6: ='FS-Month'!#REF! -> #REF! | BO6: ='FS-Month'!#REF! -> #REF! | BP6: ='FS-Month'!#REF! -> #REF! | BQ6: ='FS-Month'!#REF! -> #REF! | BR6: ='FS-Month'!#REF! -> #REF! | BS6: ='FS-Month'!#REF! -> #REF! | ... CI6: ='FS-Month'!#REF! -> #REF!
D7: ='FS-Month'!D7 -> 1 | E7: ='FS-Month'!E7 -> 2 | F7: ='FS-Month'!F7 -> 3 | G7: ='FS-Month'!G7 -> 4 | H7: ='FS-Month'!H7 -> 5 | I7: ='FS-Month'!I7 -> 6 | J7: ='FS-Month'!J7 -> 7 | K7: ='FS-Month'!K7 -> 8 | ... BK7: ='FS-Month'!BK7 -> 60 | BL7: ='FS-Month'!#REF! -> #REF! | BM7: ='FS-Month'!#REF! -> #REF! | BN7: ='FS-Month'!#REF! -> #REF! | BO7: ='FS-Month'!#REF! -> #REF! | BP7: ='FS-Month'!#REF! -> #REF! | BQ7: ='FS-Month'!#REF! -> #REF! | BR7: ='FS-Month'!#REF! -> #REF! | BS7: ='FS-Month'!#REF! -> #REF! | ... CI7: ='FS-Month'!#REF! -> #REF!
A11: P&L Bar Chart
A13: ='FS-Month'!A12 -> Revenue | D13: ='FS-Month'!D12 -> 0 | E13: ='FS-Month'!E12 -> 0 | F13: ='FS-Month'!F12 -> 0 | G13: ='FS-Month'!G12 -> 0 | H13: ='FS-Month'!H12 -> 0 | I13: ='FS-Month'!I12 -> 0 | J13: ='FS-Month'!J12 -> 0 | K13: ='FS-Month'!K12 -> 0 | ... BK13: ='FS-Month'!BK12 -> 915792.66 | BL13: ='FS-Month'!#REF! -> #REF! | BM13: ='FS-Month'!#REF! -> #REF! | BN13: ='FS-Month'!#REF! -> #REF! | BO13: ='FS-Month'!#REF! -> #REF! | BP13: ='FS-Month'!#REF! -> #REF! | BQ13: ='FS-Month'!#REF! -> #REF! | BR13: ='FS-Month'!#REF! -> #REF! | BS13: ='FS-Month'!#REF! -> #REF! | ... CI13: ='FS-Month'!#REF! -> #REF!
A14: ='FS-Month'!A18 -> COGS | D14: ='FS-Month'!D18*-1 -> 0 | E14: ='FS-Month'!E18*-1 -> 0 | F14: ='FS-Month'!F18*-1 -> 0 | G14: ='FS-Month'!G18*-1 -> 0 | H14: ='FS-Month'!H18*-1 -> 0 | I14: ='FS-Month'!I18*-1 -> 0 | J14: ='FS-Month'!J18*-1 -> 0 | K14: ='FS-Month'!K18*-1 -> 0 | ... BK14: ='FS-Month'!BK18*-1 -> -325382.93 | BL14: ='FS-Month'!#REF!*-1 -> #REF! | BM14: ='FS-Month'!#REF!*-1 -> #REF! | BN14: ='FS-Month'!#REF!*-1 -> #REF! | BO14: ='FS-Month'!#REF!*-1 -> #REF! | BP14: ='FS-Month'!#REF!*-1 -> #REF! | BQ14: ='FS-Month'!#REF!*-1 -> #REF! | BR14: ='FS-Month'!#REF!*-1 -> #REF! | BS14: ='FS-Month'!#REF!*-1 -> #REF! | ... CI14: ='FS-Month'!#REF!*-1 -> #REF!
A15: ='FS-Month'!A25 -> SG&A | D15: ='FS-Month'!D25*-1 -> -20458.333 | E15: ='FS-Month'!E25*-1 -> -6875 | F15: ='FS-Month'!F25*-1 -> -9875 | G15: ='FS-Month'!G25*-1 -> -21958.333 | H15: ='FS-Month'!H25*-1 -> -15958.333 | I15: ='FS-Month'!I25*-1 -> -16179.583 | J15: ='FS-Month'!J25*-1 -> -21500.5 | K15: ='FS-Month'!K25*-1 -> -18500.5 | ... BK15: ='FS-Month'!BK25*-1 -> -194521.06 | BL15: ='FS-Month'!#REF!*-1 -> #REF! | BM15: ='FS-Month'!#REF!*-1 -> #REF! | BN15: ='FS-Month'!#REF!*-1 -> #REF! | BO15: ='FS-Month'!#REF!*-1 -> #REF! | BP15: ='FS-Month'!#REF!*-1 -> #REF! | BQ15: ='FS-Month'!#REF!*-1 -> #REF! | BR15: ='FS-Month'!#REF!*-1 -> #REF! | BS15: ='FS-Month'!#REF!*-1 -> #REF! | ... CI15: ='FS-Month'!#REF!*-1 -> #REF!
A16: CAPEX | D16: ='FS-Month'!D86*-1 -> 0 | E16: ='FS-Month'!E86*-1 -> 0 | F16: ='FS-Month'!F86*-1 -> 0 | G16: ='FS-Month'!G86*-1 -> 0 | H16: ='FS-Month'!H86*-1 -> 0 | I16: ='FS-Month'!I86*-1 -> 0 | J16: ='FS-Month'!J86*-1 -> 0 | K16: ='FS-Month'!K86*-1 -> 0 | ... BK16: ='FS-Month'!BK86*-1 -> 0 | BL16: ='FS-Month'!#REF!*-1 -> #REF! | BM16: ='FS-Month'!#REF!*-1 -> #REF! | BN16: ='FS-Month'!#REF!*-1 -> #REF! | BO16: ='FS-Month'!#REF!*-1 -> #REF! | BP16: ='FS-Month'!#REF!*-1 -> #REF! | BQ16: ='FS-Month'!#REF!*-1 -> #REF! | BR16: ='FS-Month'!#REF!*-1 -> #REF! | BS16: ='FS-Month'!#REF!*-1 -> #REF! | ... CI16: ='FS-Month'!#REF!*-1 -> #REF!
A19: Cash in the Bank
A20: Cash in the Bank | D20: ='FS-Month'!D89 -> 79541.667 | E20: ='FS-Month'!E89 -> 72666.667 | F20: ='FS-Month'!F89 -> 62791.667 | G20: ='FS-Month'!G89 -> 40833.333 | H20: ='FS-Month'!H89 -> 24875 | I20: ='FS-Month'!I89 -> 8695.4167 | J20: ='FS-Month'!J89 -> 287194.92 | K20: ='FS-Month'!K89 -> 268694.42 | ... BK20: ='FS-Month'!BK89 -> 5813323.3 | BL20: ='FS-Month'!#REF! -> #REF! | BM20: ='FS-Month'!#REF! -> #REF! | BN20: ='FS-Month'!#REF! -> #REF! | BO20: ='FS-Month'!#REF! -> #REF! | BP20: ='FS-Month'!#REF! -> #REF! | BQ20: ='FS-Month'!#REF! -> #REF! | BR20: ='FS-Month'!#REF! -> #REF! | BS20: ='FS-Month'!#REF! -> #REF! | ... CI20: ='FS-Month'!#REF! -> #REF!
A24: Use of Funds - first 18 months
A26: SG&A
A27: Ops | D27: =SUMIF('SG&A'!$D:$D,$A27,'SG&A'!F:F) -> 18166.667 | E27: =SUMIF('SG&A'!$D:$D,$A27,'SG&A'!G:G) -> 4583.3333 | F27: =SUMIF('SG&A'!$D:$D,$A27,'SG&A'!H:H) -> 4583.3333 | G27: =SUMIF('SG&A'!$D:$D,$A27,'SG&A'!I:I) -> 12083.333 | H27: =SUMIF('SG&A'!$D:$D,$A27,'SG&A'!J:J) -> 6083.3333 | I27: =SUMIF('SG&A'!$D:$D,$A27,'SG&A'!K:K) -> 6304.5833 | J27: =SUMIF('SG&A'!$D:$D,$A27,'SG&A'!L:L) -> 9333.8333 | K27: =SUMIF('SG&A'!$D:$D,$A27,'SG&A'!M:M) -> 6333.8333 | L27: =SUMIF('SG&A'!$D:$D,$A27,'SG&A'!N:N) -> 6333.8333 | M27: =SUMIF('SG&A'!$D:$D,$A27,'SG&A'!O:O) -> 9363.0833 | N27: =SUMIF('SG&A'!$D:$D,$A27,'SG&A'!P:P) -> 6363.0833 | O27: =SUMIF('SG&A'!$D:$D,$A27,'SG&A'!Q:Q) -> 11863.083 | P27: =SUMIF('SG&A'!$D:$D,$A27,'SG&A'!R:R) -> 12421.583 | Q27: =SUMIF('SG&A'!$D:$D,$A27,'SG&A'!S:S) -> 18676.083 | R27: =SUMIF('SG&A'!$D:$D,$A27,'SG&A'!T:T) -> 6676.0833 | S27: =SUMIF('SG&A'!$D:$D,$A27,'SG&A'!U:U) -> 9705.3333 | T27: =SUMIF('SG&A'!$D:$D,$A27,'SG&A'!V:V) -> 6705.3333 | U27: =SUMIF('SG&A'!$D:$D,$A27,'SG&A'!W:W) -> 56705.333
A28: R&D | D28: =SUMIF('SG&A'!$D:$D,$A28,'SG&A'!F:F) -> 0 | E28: =SUMIF('SG&A'!$D:$D,$A28,'SG&A'!G:G) -> 0 | F28: =SUMIF('SG&A'!$D:$D,$A28,'SG&A'!H:H) -> 0 | G28: =SUMIF('SG&A'!$D:$D,$A28,'SG&A'!I:I) -> 0 | H28: =SUMIF('SG&A'!$D:$D,$A28,'SG&A'!J:J) -> 0 | I28: =SUMIF('SG&A'!$D:$D,$A28,'SG&A'!K:K) -> 0 | J28: =SUMIF('SG&A'!$D:$D,$A28,'SG&A'!L:L) -> 0 | K28: =SUMIF('SG&A'!$D:$D,$A28,'SG&A'!M:M) -> 0 | L28: =SUMIF('SG&A'!$D:$D,$A28,'SG&A'!N:N) -> 0 | M28: =SUMIF('SG&A'!$D:$D,$A28,'SG&A'!O:O) -> 0 | N28: =SUMIF('SG&A'!$D:$D,$A28,'SG&A'!P:P) -> 0 | O28: =SUMIF('SG&A'!$D:$D,$A28,'SG&A'!Q:Q) -> 0 | P28: =SUMIF('SG&A'!$D:$D,$A28,'SG&A'!R:R) -> 0 | Q28: =SUMIF('SG&A'!$D:$D,$A28,'SG&A'!S:S) -> 0 | R28: =SUMIF('SG&A'!$D:$D,$A28,'SG&A'!T:T) -> 0 | S28: =SUMIF('SG&A'!$D:$D,$A28,'SG&A'!U:U) -> 0 | T28: =SUMIF('SG&A'!$D:$D,$A28,'SG&A'!V:V) -> 0 | U28: =SUMIF('SG&A'!$D:$D,$A28,'SG&A'!W:W) -> 0
A29: Growth | D29: =SUMIF('SG&A'!$D:$D,$A29,'SG&A'!F:F) -> 0 | E29: =SUMIF('SG&A'!$D:$D,$A29,'SG&A'!G:G) -> 0 | F29: =SUMIF('SG&A'!$D:$D,$A29,'SG&A'!H:H) -> 3000 | G29: =SUMIF('SG&A'!$D:$D,$A29,'SG&A'!I:I) -> 3000 | H29: =SUMIF('SG&A'!$D:$D,$A29,'SG&A'!J:J) -> 3000 | I29: =SUMIF('SG&A'!$D:$D,$A29,'SG&A'!K:K) -> 3000 | J29: =SUMIF('SG&A'!$D:$D,$A29,'SG&A'!L:L) -> 3000 | K29: =SUMIF('SG&A'!$D:$D,$A29,'SG&A'!M:M) -> 3000 | L29: =SUMIF('SG&A'!$D:$D,$A29,'SG&A'!N:N) -> 3000 | M29: =SUMIF('SG&A'!$D:$D,$A29,'SG&A'!O:O) -> 3000 | N29: =SUMIF('SG&A'!$D:$D,$A29,'SG&A'!P:P) -> 3000 | O29: =SUMIF('SG&A'!$D:$D,$A29,'SG&A'!Q:Q) -> 3000 | P29: =SUMIF('SG&A'!$D:$D,$A29,'SG&A'!R:R) -> 7500 | Q29: =SUMIF('SG&A'!$D:$D,$A29,'SG&A'!S:S) -> 7500 | R29: =SUMIF('SG&A'!$D:$D,$A29,'SG&A'!T:T) -> 7500 | S29: =SUMIF('SG&A'!$D:$D,$A29,'SG&A'!U:U) -> 7500 | T29: =SUMIF('SG&A'!$D:$D,$A29,'SG&A'!V:V) -> 7500 | U29: =SUMIF('SG&A'!$D:$D,$A29,'SG&A'!W:W) -> 7500
A31: COGS
A32: Ops | D32: =SUMIF(COGS!$C:$C,$A32,COGS!E:E) -> 0 | E32: =SUMIF(COGS!$C:$C,$A32,COGS!F:F) -> 0 | F32: =SUMIF(COGS!$C:$C,$A32,COGS!G:G) -> 0 | G32: =SUMIF(COGS!$C:$C,$A32,COGS!H:H) -> 0 | H32: =SUMIF(COGS!$C:$C,$A32,COGS!I:I) -> 0 | I32: =SUMIF(COGS!$C:$C,$A32,COGS!J:J) -> 0 | J32: =SUMIF(COGS!$C:$C,$A32,COGS!K:K) -> 0 | K32: =SUMIF(COGS!$C:$C,$A32,COGS!L:L) -> 0 | L32: =SUMIF(COGS!$C:$C,$A32,COGS!M:M) -> 0 | M32: =SUMIF(COGS!$C:$C,$A32,COGS!N:N) -> 0 | N32: =SUMIF(COGS!$C:$C,$A32,COGS!O:O) -> 0 | O32: =SUMIF(COGS!$C:$C,$A32,COGS!P:P) -> 0 | P32: =SUMIF(COGS!$C:$C,$A32,COGS!Q:Q) -> 0 | Q32: =SUMIF(COGS!$C:$C,$A32,COGS!R:R) -> 0 | R32: =SUMIF(COGS!$C:$C,$A32,COGS!S:S) -> 0 | S32: =SUMIF(COGS!$C:$C,$A32,COGS!T:T) -> 0 | T32: =SUMIF(COGS!$C:$C,$A32,COGS!U:U) -> 0 | U32: =SUMIF(COGS!$C:$C,$A32,COGS!V:V) -> 0
A33: R&D | D33: =SUMIF(COGS!$C:$C,$A33,COGS!E:E) -> 0 | E33: =SUMIF(COGS!$C:$C,$A33,COGS!F:F) -> 0 | F33: =SUMIF(COGS!$C:$C,$A33,COGS!G:G) -> 0 | G33: =SUMIF(COGS!$C:$C,$A33,COGS!H:H) -> 0 | H33: =SUMIF(COGS!$C:$C,$A33,COGS!I:I) -> 0 | I33: =SUMIF(COGS!$C:$C,$A33,COGS!J:J) -> 0 | J33: =SUMIF(COGS!$C:$C,$A33,COGS!K:K) -> 0 | K33: =SUMIF(COGS!$C:$C,$A33,COGS!L:L) -> 0 | L33: =SUMIF(COGS!$C:$C,$A33,COGS!M:M) -> 0 | M33: =SUMIF(COGS!$C:$C,$A33,COGS!N:N) -> 0 | N33: =SUMIF(COGS!$C:$C,$A33,COGS!O:O) -> 0 | O33: =SUMIF(COGS!$C:$C,$A33,COGS!P:P) -> 0 | P33: =SUMIF(COGS!$C:$C,$A33,COGS!Q:Q) -> 0 | Q33: =SUMIF(COGS!$C:$C,$A33,COGS!R:R) -> 0 | R33: =SUMIF(COGS!$C:$C,$A33,COGS!S:S) -> 0 | S33: =SUMIF(COGS!$C:$C,$A33,COGS!T:T) -> 0 | T33: =SUMIF(COGS!$C:$C,$A33,COGS!U:U) -> 0 | U33: =SUMIF(COGS!$C:$C,$A33,COGS!V:V) -> 0
A34: Growth | D34: =SUMIF(COGS!$C:$C,$A34,COGS!E:E) -> 0 | E34: =SUMIF(COGS!$C:$C,$A34,COGS!F:F) -> 0 | F34: =SUMIF(COGS!$C:$C,$A34,COGS!G:G) -> 0 | G34: =SUMIF(COGS!$C:$C,$A34,COGS!H:H) -> 0 | H34: =SUMIF(COGS!$C:$C,$A34,COGS!I:I) -> 0 | I34: =SUMIF(COGS!$C:$C,$A34,COGS!J:J) -> 0 | J34: =SUMIF(COGS!$C:$C,$A34,COGS!K:K) -> 0 | K34: =SUMIF(COGS!$C:$C,$A34,COGS!L:L) -> 0 | L34: =SUMIF(COGS!$C:$C,$A34,COGS!M:M) -> 0 | M34: =SUMIF(COGS!$C:$C,$A34,COGS!N:N) -> 0 | N34: =SUMIF(COGS!$C:$C,$A34,COGS!O:O) -> 0 | O34: =SUMIF(COGS!$C:$C,$A34,COGS!P:P) -> 0 | P34: =SUMIF(COGS!$C:$C,$A34,COGS!Q:Q) -> 0 | Q34: =SUMIF(COGS!$C:$C,$A34,COGS!R:R) -> 0 | R34: =SUMIF(COGS!$C:$C,$A34,COGS!S:S) -> 0 | S34: =SUMIF(COGS!$C:$C,$A34,COGS!T:T) -> 0 | T34: =SUMIF(COGS!$C:$C,$A34,COGS!U:U) -> 0 | U34: =SUMIF(COGS!$C:$C,$A34,COGS!V:V) -> 0
A37: Total
A38: Ops | D38: =D27+D32 -> 18166.667 | E38: =E27+E32 -> 4583.3333 | F38: =F27+F32 -> 4583.3333 | G38: =G27+G32 -> 12083.333 | H38: =H27+H32 -> 6083.3333 | I38: =I27+I32 -> 6304.5833 | J38: =J27+J32 -> 9333.8333 | K38: =K27+K32 -> 6333.8333 | ... U38: =U27+U32 -> 56705.333
A39: R&D | D39: =D28+D33 -> 0 | E39: =E28+E33 -> 0 | F39: =F28+F33 -> 0 | G39: =G28+G33 -> 0 | H39: =H28+H33 -> 0 | I39: =I28+I33 -> 0 | J39: =J28+J33 -> 0 | K39: =K28+K33 -> 0 | ... U39: =U28+U33 -> 0
A40: Growth | D40: =D29+D34 -> 0 | E40: =E29+E34 -> 0 | F40: =F29+F34 -> 3000 | G40: =G29+G34 -> 3000 | H40: =H29+H34 -> 3000 | I40: =I29+I34 -> 3000 | J40: =J29+J34 -> 3000 | K40: =K29+K34 -> 3000 | ... U40: =U29+U34 -> 7500
A41: Other | D41: =D42-D38-D39-D40 -> 2291.6667 | E41: =E42-E38-E39-E40 -> 2291.6667 | F41: =F42-F38-F39-F40 -> 2291.6667 | G41: =G42-G38-G39-G40 -> 6875 | H41: =H42-H38-H39-H40 -> 6875 | I41: =I42-I38-I39-I40 -> 6875 | J41: =J42-J38-J39-J40 -> 9166.6667 | K41: =K42-K38-K39-K40 -> 9166.6667 | ... U41: =U42-U38-U39-U40 -> 30250
A42: Total Expenses | D42: ='FS-Month'!D25+'FS-Month'!D18 -> 20458.333 | E42: ='FS-Month'!E25+'FS-Month'!E18 -> 6875 | F42: ='FS-Month'!F25+'FS-Month'!F18 -> 9875 | G42: ='FS-Month'!G25+'FS-Month'!G18 -> 21958.333 | H42: ='FS-Month'!H25+'FS-Month'!H18 -> 15958.333 | I42: ='FS-Month'!I25+'FS-Month'!I18 -> 16179.583 | J42: ='FS-Month'!J25+'FS-Month'!J18 -> 21500.5 | K42: ='FS-Month'!K25+'FS-Month'!K18 -> 18500.5 | ... U42: ='FS-Month'!U25+'FS-Month'!U18 -> 94455.333
A45: Pie Chart
A46: Ops | C46: =D46/D$50 -> 0.39203631 | D46: =SUM(38:38) -> 212285.08
A47: R&D | C47: =D47/D$50 -> 0 | D47: =SUM(39:39) -> 0
A48: Growth | C48: =D48/D$50 -> 0.13850584 | D48: =SUM(40:40) -> 75000
A49: Other | C49: =D49/D$50 -> 0.46945785 | D49: =SUM(41:41) -> 254208.33
A50: Total Expenses | D50: =SUM(42:42) -> 541493.42

Sheet FS-Annual
A1: =Settings!C5 -> VReeMind
A2: Financial Statement (Annual)
A3: =+TODAY() -> 44143
C4: D-O | D4: P-AA | E4: AB-AM | F4: AN-AY | G4: AZ-BK | H4: BL-BW | I4: BX-CI
A6: Net Present Value | B6: =NPV(Settings!C21,C111:I111) -> 51678189 | C6: =Settings!C7 -> 43466 | D6: =EDATE(C6,12) -> 43831 | E6: =EDATE(D6,12) -> 44197 | F6: =EDATE(E6,12) -> 44562 | G6: =EDATE(F6,12) -> 44927 | H6: =EDATE(G6,12) -> 45292 | I6: =EDATE(H6,12) -> 45658 | J6: CAGR
B7: Unit | C7: 1 | D7: =C7+1 -> 2 | E7: =D7+1 -> 3 | F7: =E7+1 -> 4 | G7: =F7+1 -> 5 | H7: =G7+1 -> 6 | I7: =H7+1 -> 7 | J7: Y3-Y7
A9: KEY INDICATORS
A17: INCOME STATEMENT
A19: Revenue | B19: =Settings!$C$6 -> USD | C19: =SUM(C20:C23) -> 0 | D19: =SUM(D20:D23) -> 208701.37 | E19: =SUM(E20:E23) -> 3766395.6 | F19: =SUM(F20:F23) -> 7386963.3 | G19: =SUM(G20:G23) -> 11444990 | H19: =SUM(H20:H23) -> 20542725 | I19: =SUM(I20:I23) -> 36015130 | J19: =IF(IFERROR((I19/E19)^(1/5)-1,"-")<0,"-",IFERROR((I19/E19)^(1/5)-1,"-")) -> 0.57076715
A20: ='FS-Month'!A13 -> SOURCE #1: Self-Service Subscriptions | B20: =Settings!$C$6 -> USD | C20: =SUM('FS-Month'!D13:O13) -> 0 | D20: =SUM('FS-Month'!P13:AA13) -> 208701.37 | E20: =SUM('FS-Month'!AB13:AM13) -> 3485595.6 | F20: =SUM('FS-Month'!AN13:AY13) -> 5889363.3 | G20: =SUM('FS-Month'!AZ13:BK13) -> 8956669.8 | H20: =SUM('FS-Month'!BL13:BW13) -> 15970845 | I20: =SUM('FS-Month'!BX13:CI13) -> 28464922 | J20: =IF(IFERROR((I20/E20)^(1/5)-1,"-")<0,"-",IFERROR((I20/E20)^(1/5)-1,"-")) -> 0.52197178
A21: ='FS-Month'!A14 -> SOURCE #2: Inbound Sales | B21: =Settings!$C$6 -> USD | C21: =SUM('FS-Month'!D14:O14) -> 0 | D21: =SUM('FS-Month'!P14:AA14) -> 0 | E21: =SUM('FS-Month'!AB14:AM14) -> 0 | F21: =SUM('FS-Month'!AN14:AY14) -> 0 | G21: =SUM('FS-Month'!AZ14:BK14) -> 0 | H21: =SUM('FS-Month'!BL14:BW14) -> 0 | I21: =SUM('FS-Month'!BX14:CI14) -> 0 | J21: =IF(IFERROR((I21/E21)^(1/5)-1,"-")<0,"-",IFERROR((I21/E21)^(1/5)-1,"-")) -> -
A22: ='FS-Month'!A15 -> SOURCE #3: Outbound Sales | B22: =Settings!$C$6 -> USD | C22: =SUM('FS-Month'!D15:O15) -> 0 | D22: =SUM('FS-Month'!P15:AA15) -> 0 | E22: =SUM('FS-Month'!AB15:AM15) -> 0 | F22: =SUM('FS-Month'!AN15:AY15) -> 0 | G22: =SUM('FS-Month'!AZ15:BK15) -> 0 | H22: =SUM('FS-Month'!BL15:BW15) -> 0 | I22: =SUM('FS-Month'!BX15:CI15) -> 0 | J22: =IF(IFERROR((I22/E22)^(1/5)-1,"-")<0,"-",IFERROR((I22/E22)^(1/5)-1,"-")) -> -
A23: ='FS-Month'!A16 -> Renewals | B23: =Settings!$C$6 -> USD | C23: =SUM('FS-Month'!D16:O16) -> 0 | D23: =SUM('FS-Month'!P16:AA16) -> 0 | E23: =SUM('FS-Month'!AB16:AM16) -> 280800 | F23: =SUM('FS-Month'!AN16:AY16) -> 1497600 | G23: =SUM('FS-Month'!AZ16:BK16) -> 2488320 | H23: =SUM('FS-Month'!BL16:BW16) -> 4571880 | I23: =SUM('FS-Month'!BX16:CI16) -> 7550208 | J23: =IF(IFERROR((I23/E23)^(1/5)-1,"-")<0,"-",IFERROR((I23/E23)^(1/5)-1,"-")) -> 0.9315785
J24: =IF(IFERROR((I24/E24)^(1/5)-1,"-")<0,"-",IFERROR((I24/E24)^(1/5)-1,"-")) -> -
A25: COGS | B25: =Settings!$C$6 -> USD | C25: =SUM(C26:C28) -> 0 | D25: =SUM(D26:D28) -> 381439.48 | E25: =SUM(E26:E28) -> 2955395.2 | F25: =SUM(F26:F28) -> 5162194.7 | G25: =SUM(G26:G28) -> 8131569.5 | H25: =SUM(H26:H28) -> 12968149 | I25: =SUM(I26:I28) -> 21692893 | J25: =IF(IFERROR((I25/E25)^(1/5)-1,"-")<0,"-",IFERROR((I25/E25)^(1/5)-1,"-")) -> 0.48984259
A26: ='FS-Month'!A19 -> CATEGORY #1: Hosting/Customer Service | B26: =Settings!$C$6 -> USD | C26: =SUM('FS-Month'!D19:O19) -> 0 | D26: =SUM('FS-Month'!P19:AA19) -> 594 | E26: =SUM('FS-Month'!AB19:AM19) -> 9596.7234 | F26: =SUM('FS-Month'!AN19:AY19) -> 25077.577 | G26: =SUM('FS-Month'!AZ19:BK19) -> 47743.097 | H26: =SUM('FS-Month'!BL19:BW19) -> 80927.685 | I26: =SUM('FS-Month'!BX19:CI19) -> 129513.24 | J26: =IF(IFERROR((I26/E26)^(1/5)-1,"-")<0,"-",IFERROR((I26/E26)^(1/5)-1,"-")) -> 0.68282222
A27: ='FS-Month'!A20 -> CATEGORY #2: Partnership Commissions | B27: =Settings!$C$6 -> USD | C27: =SUM('FS-Month'!D20:O20) -> 0 | D27: =SUM('FS-Month'!P20:AA20) -> 318235.07 | E27: =SUM('FS-Month'!AB20:AM20) -> 1815879.8 | F27: =SUM('FS-Month'!AN20:AY20) -> 2921028.2 | G27: =SUM('FS-Month'!AZ20:BK20) -> 4650329.5 | H27: =SUM('FS-Month'!BL20:BW20) -> 6724404 | I27: =SUM('FS-Month'!BX20:CI20) -> 10758841 | J27: =IF(IFERROR((I27/E27)^(1/5)-1,"-")<0,"-",IFERROR((I27/E27)^(1/5)-1,"-")) -> 0.4273671
A28: ='FS-Month'!A21 -> CATEGORY #3: App Store Fees | B28: =Settings!$C$6 -> USD | C28: =SUM('FS-Month'!D21:O21) -> 0 | D28: =SUM('FS-Month'!P21:AA21) -> 62610.411 | E28: =SUM('FS-Month'!AB21:AM21) -> 1129918.7 | F28: =SUM('FS-Month'!AN21:AY21) -> 2216089 | G28: =SUM('FS-Month'!AZ21:BK21) -> 3433496.9 | H28: =SUM('FS-Month'!BL21:BW21) -> 6162817.4 | I28: =SUM('FS-Month'!BX21:CI21) -> 10804539 | J28: =IF(IFERROR((I28/E28)^(1/5)-1,"-")<0,"-",IFERROR((I28/E28)^(1/5)-1,"-")) -> 0.57076715
A29: Gross Profit | B29: =Settings!$C$6 -> USD | C29: =C19-C25 -> 0 | D29: =D19-D25 -> -172738.11 | E29: =E19-E25 -> 811000.43 | F29: =F19-F25 -> 2224768.6 | G29: =G19-G25 -> 3313420.3 | H29: =H19-H25 -> 7574575.6 | I29: =I19-I25 -> 14322237 | J29: =IF(IFERROR((I29/E29)^(1/5)-1,"-")<0,"-",IFERROR((I29/E29)^(1/5)-1,"-")) -> 0.77581595
A30: Gross margin | B30: % | C30: =IFERROR(C29/C$19,"-") -> - | D30: =IFERROR(D29/D$19,"-") -> -0.82768077 | E30: =IFERROR(E29/E$19,"-") -> 0.21532534 | F30: =IFERROR(F29/F$19,"-") -> 0.30117499 | G30: =IFERROR(G29/G$19,"-") -> 0.28950836 | H30: =IFERROR(H29/H$19,"-") -> 0.36872303 | I30: =IFERROR(I29/I$19,"-") -> 0.39767277 | J30: =IF(IFERROR((I30/E30)^(1/5)-1,"-")<0,"-",IFERROR((I30/E30)^(1/5)-1,"-")) -> 0.13054054
D31: =(D28)=D19*0.3 -> TRUE | E31: =(E28)=E19*0.3 -> TRUE | F31: =(F28)=F19*0.3 -> TRUE | G31: =(G28)=G19*0.3 -> TRUE | H31: =(H28)=H19*0.3 -> TRUE | I31: =(I28)=I19*0.3 -> TRUE
A32: SG&A | B32: =Settings!$C$6 -> USD | C32: =SUM(C33:C40) -> 220770.33 | D32: =SUM(D33:D40) -> 594955.08 | E32: =SUM(E33:E40) -> 985808.37 | F32: =SUM(F33:F40) -> 1517992.1 | G32: =SUM(G33:G40) -> 1964791.9 | H32: =SUM(H33:H40) -> 2421328 | I32: =SUM(I33:I40) -> 2518233.2 | J32: =IF(IFERROR((I32/E32)^(1/5)-1,"-")<0,"-",IFERROR((I32/E32)^(1/5)-1,"-")) -> 0.20631489
A33: ='FS-Month'!A26 -> PAYROLL | B33: =Settings!$C$6 -> USD | C33: =SUM('FS-Month'!D26:O26) -> 148958.33 | D33: =SUM('FS-Month'!P26:AA26) -> 399345.83 | E33: =SUM('FS-Month'!AB26:AM26) -> 742957.87 | F33: =SUM('FS-Month'!AN26:AY26) -> 1183631.6 | G33: =SUM('FS-Month'!AZ26:BK26) -> 1511676.4 | H33: =SUM('FS-Month'!BL26:BW26) -> 1870311.3 | I33: =SUM('FS-Month'!BX26:CI26) -> 1965783.2 | J33: =IF(IFERROR((I33/E33)^(1/5)-1,"-")<0,"-",IFERROR((I33/E33)^(1/5)-1,"-")) -> 0.21482658
A34: ='FS-Month'!A27 -> MARKETING & GROWTH | B34: =Settings!$C$6 -> USD | C34: =SUM('FS-Month'!D27:O27) -> 30000 | D34: =SUM('FS-Month'!P27:AA27) -> 90000 | E34: =SUM('FS-Month'!AB27:AM27) -> 150000 | F34: =SUM('FS-Month'!AN27:AY27) -> 240000 | G34: =SUM('FS-Month'!AZ27:BK27) -> 360000 | H34: =SUM('FS-Month'!BL27:BW27) -> 480000 | I34: =SUM('FS-Month'!BX27:CI27) -> 480000 | J34: =IF(IFERROR((I34/E34)^(1/5)-1,"-")<0,"-",IFERROR((I34/E34)^(1/5)-1,"-")) -> 0.26191469
A35: ='FS-Month'!A28 -> LEGAL, ADVISORY, PROF. SERVICES | B35: =Settings!$C$6 -> USD | C35: =SUM('FS-Month'!D28:O28) -> 16000 | D35: =SUM('FS-Month'!P28:AA28) -> 74000 | E35: =SUM('FS-Month'!AB28:AM28) -> 31000 | F35: =SUM('FS-Month'!AN28:AY28) -> 40000 | G35: =SUM('FS-Month'!AZ28:BK28) -> 40000 | H35: =SUM('FS-Month'!BL28:BW28) -> 40000 | I35: =SUM('FS-Month'!BX28:CI28) -> 40000 | J35: =IF(IFERROR((I35/E35)^(1/5)-1,"-")<0,"-",IFERROR((I35/E35)^(1/5)-1,"-")) -> 0.052300216
A36: ='FS-Month'!A29 -> WFA Stipend | B36: =Settings!$C$6 -> USD | C36: =SUM('FS-Month'!D29:O29) -> 21000 | D36: =SUM('FS-Month'!P29:AA29) -> 21000 | E36: =SUM('FS-Month'!AB29:AM29) -> 42000 | F36: =SUM('FS-Month'!AN29:AY29) -> 27000 | G36: =SUM('FS-Month'!AZ29:BK29) -> 15000 | H36: =SUM('FS-Month'!BL29:BW29) -> 12000 | I36: =SUM('FS-Month'!BX29:CI29) -> 12000 | J36: =IF(IFERROR((I36/E36)^(1/5)-1,"-")<0,"-",IFERROR((I36/E36)^(1/5)-1,"-")) -> -
A37: ='FS-Month'!A30 -> TECH SUPPORT & SERVICES | B37: =Settings!$C$6 -> USD | C37: =SUM('FS-Month'!D30:O30) -> 1812 | D37: =SUM('FS-Month'!P30:AA30) -> 5609.25 | E37: =SUM('FS-Month'!AB30:AM30) -> 9850.5 | F37: =SUM('FS-Month'!AN30:AY30) -> 13360.5 | G37: =SUM('FS-Month'!AZ30:BK30) -> 15115.5 | H37: =SUM('FS-Month'!BL30:BW30) -> 17016.75 | I37: =SUM('FS-Month'!BX30:CI30) -> 18450 | J37: =IF(IFERROR((I37/E37)^(1/5)-1,"-")<0,"-",IFERROR((I37/E37)^(1/5)-1,"-")) -> 0.13372473
A38: ='FS-Month'!A31 -> INSURANCE | B38: =Settings!$C$6 -> USD | C38: =SUM('FS-Month'!D31:O31) -> 1000 | D38: =SUM('FS-Month'!P31:AA31) -> 1000 | E38: =SUM('FS-Month'!AB31:AM31) -> 2000 | F38: =SUM('FS-Month'!AN31:AY31) -> 4000 | G38: =SUM('FS-Month'!AZ31:BK31) -> 8000 | H38: =SUM('FS-Month'!BL31:BW31) -> 2000 | I38: =SUM('FS-Month'!BX31:CI31) -> 2000 | J38: =IF(IFERROR((I38/E38)^(1/5)-1,"-")<0,"-",IFERROR((I38/E38)^(1/5)-1,"-")) -> 0
A39: ='FS-Month'!A32 -> 0 | B39: =Settings!$C$6 -> USD | C39: =SUM('FS-Month'!D32:O32) -> 0 | D39: =SUM('FS-Month'!P32:AA32) -> 0 | E39: =SUM('FS-Month'!AB32:AM32) -> 0 | F39: =SUM('FS-Month'!AN32:AY32) -> 0 | G39: =SUM('FS-Month'!AZ32:BK32) -> 0 | H39: =SUM('FS-Month'!BL32:BW32) -> 0 | I39: =SUM('FS-Month'!BX32:CI32) -> 0 | J39: =IF(IFERROR((I39/E39)^(1/5)-1,"-")<0,"-",IFERROR((I39/E39)^(1/5)-1,"-")) -> -
A40: ='FS-Month'!A33 -> OTHER EXPENSES | B40: =Settings!$C$6 -> USD | C40: =SUM('FS-Month'!D33:O33) -> 2000 | D40: =SUM('FS-Month'!P33:AA33) -> 4000 | E40: =SUM('FS-Month'!AB33:AM33) -> 8000 | F40: =SUM('FS-Month'!AN33:AY33) -> 10000 | G40: =SUM('FS-Month'!AZ33:BK33) -> 15000 | H40: =SUM('FS-Month'!BL33:BW33) -> 0 | I40: =SUM('FS-Month'!BX33:CI33) -> 0 | J40: =IF(IFERROR((I40/E40)^(1/5)-1,"-")<0,"-",IFERROR((I40/E40)^(1/5)-1,"-")) -> -
A41: EBITDA | B41: =Settings!$C$6 -> USD | C41: =C29-C32 -> -220770.33 | D41: =D29-D32 -> -767693.19 | E41: =E29-E32 -> -174807.95 | F41: =F29-F32 -> 706776.45 | G41: =G29-G32 -> 1348628.4 | H41: =H29-H32 -> 5153247.6 | I41: =I29-I32 -> 11804004 | J41: =IF(IFERROR((I41/E41)^(1/5)-1,"-")<0,"-",IFERROR((I41/E41)^(1/5)-1,"-")) -> -
A42: EBITDA margin | C42: =IFERROR(MAX((C41/C$19),0),"-") -> - | D42: =IFERROR(MAX((D41/D$19),0),"-") -> 0 | E42: =IFERROR(MAX((E41/E$19),0),"-") -> 0 | F42: =IFERROR(MAX((F41/F$19),0),"-") -> 0.09567889 | G42: =IFERROR(MAX((G41/G$19),0),"-") -> 0.1178357 | H42: =IFERROR(MAX((H41/H$19),0),"-") -> 0.25085512 | I42: =IFERROR(MAX((I41/I$19),0),"-") -> 0.32775124
A44: D&A | B44: =Settings!$C$6 -> USD | C44: =SUM('FS-Month'!D37:O37) -> 0 | D44: =SUM('FS-Month'!P37:AA37) -> 0 | E44: =SUM('FS-Month'!AB37:AM37) -> 0 | F44: =SUM('FS-Month'!AN37:AY37) -> 0 | G44: =SUM('FS-Month'!AZ37:BK37) -> 0 | H44: =SUM('FS-Month'!BL37:BW37) -> 0 | I44: =SUM('FS-Month'!BX37:CI37) -> 0 | J44: =IF(IFERROR((I44/E44)^(1/5)-1,"-")<0,"-",IFERROR((I44/E44)^(1/5)-1,"-")) -> -
A45: EBIT | B45: =Settings!$C$6 -> USD | C45: =C41-C44 -> -220770.33 | D45: =D41-D44 -> -767693.19 | E45: =E41-E44 -> -174807.95 | F45: =F41-F44 -> 706776.45 | G45: =G41-G44 -> 1348628.4 | H45: =H41-H44 -> 5153247.6 | I45: =I41-I44 -> 11804004 | J45: =IF(IFERROR((I45/E45)^(1/5)-1,"-")<0,"-",IFERROR((I45/E45)^(1/5)-1,"-")) -> -
A46: EBIT margin | C46: =IFERROR(MAX((C45/C$19),0),"-") -> - | D46: =IFERROR(MAX((D45/D$19),0),"-") -> 0 | E46: =IFERROR(MAX((E45/E$19),0),"-") -> 0 | F46: =IFERROR(MAX((F45/F$19),0),"-") -> 0.09567889 | G46: =IFERROR(MAX((G45/G$19),0),"-") -> 0.1178357 | H46: =IFERROR(MAX((H45/H$19),0),"-") -> 0.25085512
A48: Interest expense | B48: =Settings!$C$6 -> USD | C48: =SUM('FS-Month'!D41:O41) -> 0 | D48: =SUM('FS-Month'!P41:AA41) -> 0 | E48: =SUM('FS-Month'!AB41:AM41) -> 0 | F48: =SUM('FS-Month'!AN41:AY41) -> 0 | G48: =SUM('FS-Month'!AZ41:BK41) -> 0 | H48: =SUM('FS-Month'!BL41:BW41) -> 0 | I48: =SUM('FS-Month'!BB41:BM41) -> 0
A49: Income taxes | B49: =Settings!$C$6 -> USD | C49: =IF(C45>0,C45*Settings!$C$16,"0") -> 0 | D49: =IF(D45>0,D45*Settings!$C$16,"0") -> 0 | E49: =IF(E45>0,E45*Settings!$C$16,"0") -> 0 | F49: =IF(F45>0,F45*Settings!$C$16,"0") -> 0 | G49: =IF(G45>0,G45*Settings!$C$16,"0") -> 0 | H49: =IF(H45>0,H45*Settings!$C$16,"0") -> 0 | I49: =IF(I45>0,I45*Settings!$C$16,"0") -> 0 | J49: =IF(IFERROR((I49/E49)^(1/5)-1,"-")<0,"-",IFERROR((I49/E49)^(1/5)-1,"-")) -> -
A50: Net income | B50: =Settings!$C$6 -> USD | C50: =C45-C48-C49 -> -220770.33 | D50: =D45-D48-D49 -> -767693.19 | E50: =E45-E48-E49 -> -174807.95 | F50: =F45-F48-F49 -> 706776.45 | G50: =G45-G48-G49 -> 1348628.4 | H50: =H45-H48-H49 -> 5153247.6 | I50: =I45-I48-I49 -> 11804004 | J50: =IF(IFERROR((I50/E50)^(1/5)-1,"-")<0,"-",IFERROR((I50/E50)^(1/5)-1,"-")) -> -
A51: Net margin | C51: =IFERROR(C50/C19,"-") -> - | D51: =IFERROR(D50/D19,"-") -> -3.6784291 | E51: =IFERROR(E50/E19,"-") -> -0.04641253 | F51: =IFERROR(F50/F19,"-") -> 0.09567889 | G51: =IFERROR(G50/G19,"-") -> 0.1178357 | H51: =IFERROR(H50/H19,"-") -> 0.25085512 | I51: =IFERROR(I50/I19,"-") -> 0.32775124
A54: BALANCE SHEET
...

Sheet FS-Month
A1: =Settings!C5 -> VReeMind
A2: Financial Statement (Monthly)
A3: =+TODAY() -> 44143
C6: START | D6: =Settings!$C$7 -> 43466 | E6: =EDATE(D6,1) -> 43497 | F6: =EDATE(E6,1) -> 43525 | G6: =EDATE(F6,1) -> 43556 | H6: =EDATE(G6,1) -> 43586 | I6: =EDATE(H6,1) -> 43617 | J6: =EDATE(I6,1) -> 43647 | K6: =EDATE(J6,1) -> 43678 | L6: =EDATE(K6,1) -> 43709 | ... DG6: =EDATE(DF6,1) -> 46722
B7: Unit | D7: 1 | E7: =D7+1 -> 2 | F7: =E7+1 -> 3 | G7: =F7+1 -> 4 | H7: =G7+1 -> 5 | I7: =H7+1 -> 6 | J7: =I7+1 -> 7 | K7: =J7+1 -> 8 | L7: =K7+1 -> 9 | ... DG7: =DF7+1 -> 108
A9: KEY INDICATORS
A10: INCOME STATEMENT
Y11: =Y12=Revenue!Y21 -> TRUE | Z11: =Z12=Revenue!Z21 -> TRUE | AA11: =AA12=Revenue!AA21 -> TRUE | AB11: =AB12=Revenue!AB21 -> TRUE | AC11: =AC12=Revenue!AC21 -> TRUE | AD11: =AD12=Revenue!AD21 -> TRUE | AE11: =AE12=Revenue!AE21 -> TRUE | AF11: =AF12=Revenue!AF21 -> TRUE | ... DG11: =DG12=Revenue!DG21 -> TRUE
A12: Revenue | B12: =Settings!$C$6 -> USD | D12: =Revenue!D56 -> 0 | E12: =SUM(E13:E16) -> 0 | F12: =SUM(F13:F16) -> 0 | G12: =SUM(G13:G16) -> 0 | H12: =SUM(H13:H16) -> 0 | I12: =SUM(I13:I16) -> 0 | J12: =SUM(J13:J16) -> 0 | K12: =SUM(K13:K16) -> 0 | L12: =SUM(L13:L16) -> 0 | ... DG12: =SUM(DG13:DG16) -> 5861415.3
A13: =Revenue!A17 -> SOURCE #1: Self-Service Subscriptions | B13: =Settings!$C$6 -> USD | D13: =Revenue!D17 -> 0 | E13: =Revenue!E17 -> 0 | F13: =Revenue!F17 -> 0 | G13: =Revenue!G17 -> 0 | H13: =Revenue!H17 -> 0 | I13: =Revenue!I17 -> 0 | J13: =Revenue!J17 -> 0 | K13: =Revenue!K17 -> 0 | ... DG13: =Revenue!DG17 -> 5861415.3
A14: =Revenue!A18 -> SOURCE #2: Inbound Sales | B14: =Settings!$C$6 -> USD | D14: =Revenue!D18 -> 0 | E14: =Revenue!E18 -> 0 | F14: =Revenue!F18 -> 0 | G14: =Revenue!G18 -> 0 | H14: =Revenue!H18 -> 0 | I14: =Revenue!I18 -> 0 | J14: =Revenue!J18 -> 0 | K14: =Revenue!K18 -> 0 | ... DG14: =Revenue!DG18 -> 0
A15: =Revenue!A19 -> SOURCE #3: Outbound Sales | B15: =Settings!$C$6 -> USD | D15: =Revenue!D19 -> 0 | E15: =Revenue!E19 -> 0 | F15: =Revenue!F19 -> 0 | G15: =Revenue!G19 -> 0 | H15: =Revenue!H19 -> 0 | I15: =Revenue!I19 -> 0 | J15: =Revenue!J19 -> 0 | K15: =Revenue!K19 -> 0 | ... DG15: =Revenue!DG19 -> 0
A16: =Revenue!A20 -> Renewals | B16: =Settings!$C$6 -> USD | D16: =Revenue!D20 -> 0 | E16: =Revenue!E20 -> 0 | F16: =Revenue!F20 -> 0 | G16: =Revenue!G20 -> 0 | H16: =Revenue!H20 -> 0 | I16: =Revenue!I20 -> 0 | J16: =Revenue!J20 -> 0 | K16: =Revenue!K20 -> 0 | ... DG16: =Revenue!DG20 -> ERR
A18: COGS | B18: =Settings!$C$6 -> USD | D18: =SUM(D19:D21) -> 0 | E18: =SUM(E19:E21) -> 0 | F18: =SUM(F19:F21) -> 0 | G18: =SUM(G19:G21) -> 0 | H18: =SUM(H19:H21) -> 0 | I18: =SUM(I19:I21) -> 0 | J18: =SUM(J19:J21) -> 0 | K18: =SUM(K19:K21) -> 0 | ... DG18: =SUM(DG19:DG21) -> 1797470.1
A19: =COGS!A19 -> CATEGORY #1: Hosting/Customer Service | B19: =Settings!$C$6 -> USD | D19: =COGS!E19 -> 0 | E19: =COGS!F19 -> 0 | F19: =COGS!G19 -> 0 | G19: =COGS!H19 -> 0 | H19: =COGS!I19 -> 0 | I19: =COGS!J19 -> 0 | J19: =COGS!K19 -> 0 | K19: =COGS!L19 -> 0 | ... DG19: =COGS!DH19 -> 39045.523
A20: =COGS!A20 -> CATEGORY #2: Partnership Commissions | B20: =Settings!$C$6 -> USD | D20: =COGS!E20 -> 0 | E20: =COGS!F20 -> 0 | F20: =COGS!G20 -> 0 | G20: =COGS!H20 -> 0 | H20: =COGS!I20 -> 0 | I20: =COGS!J20 -> 0 | J20: =COGS!K20 -> 0 | K20: =COGS!L20 -> 0 | ... DG20: =COGS!DH20 -> 0
A21: =COGS!A21 -> CATEGORY #3: App Store Fees | B21: =Settings!$C$6 -> USD | D21: =COGS!E21 -> 0 | E21: =COGS!F21 -> 0 | F21: =COGS!G21 -> 0 | G21: =COGS!H21 -> 0 | H21: =COGS!I21 -> 0 | I21: =COGS!J21 -> 0 | J21: =COGS!K21 -> 0 | K21: =COGS!L21 -> 0 | ... DG21: =COGS!DH21 -> 1758424.6
A22: Gross Profit | B22: =Settings!$C$6 -> USD | D22: =D12-D18 -> 0 | E22: =E12-E18 -> 0 | F22: =F12-F18 -> 0 | G22: =G12-G18 -> 0 | H22: =H12-H18 -> 0 | I22: =I12-I18 -> 0 | J22: =J12-J18 -> 0 | K22: =K12-K18 -> 0 | ... DG22: =DG12-DG18 -> 4063945.2
A23: Gross margin | B23: % | D23: =IFERROR(D22/D$12,"-") -> - | E23: =IFERROR(E22/E$12,"-") -> - | F23: =IFERROR(F22/F$12,"-") -> - | G23: =IFERROR(G22/G$12,"-") -> - | H23: =IFERROR(H22/H$12,"-") -> - | I23: =IFERROR(I22/I$12,"-") -> - | J23: =IFERROR(J22/J$12,"-") -> - | K23: =IFERROR(K22/K$12,"-") -> - | ... DG23: =IFERROR(DG22/DG$12,"-") -> 0.69333855
A25: SG&A | B25: =Settings!$C$6 -> USD | D25: =SUM(D26:D33) -> 20458.333 | E25: =SUM(E26:E33) -> 6875 | F25: =SUM(F26:F33) -> 9875 | G25: =SUM(G26:G33) -> 21958.333 | H25: =SUM(H26:H33) -> 15958.333 | I25: =SUM(I26:I33) -> 16179.583 | J25: =SUM(J26:J33) -> 21500.5 | K25: =SUM(K26:K33) -> 18500.5 | ... DG25: =SUM(DG26:DG33) -> 219713.63
A26: ='SG&A'!A22 -> PAYROLL | B26: =Settings!$C$6 -> USD | D26: ='SG&A'!F22 -> 11458.333 | E26: ='SG&A'!G22 -> 6875 | F26: ='SG&A'!H22 -> 6875 | G26: ='SG&A'!I22 -> 11458.333 | H26: ='SG&A'!J22 -> 11458.333 | I26: ='SG&A'!K22 -> 11458.333 | J26: ='SG&A'!L22 -> 13750 | K26: ='SG&A'!M22 -> 13750 | ... DG26: ='SG&A'!DI22 -> 169176.13
A27: ='SG&A'!A23 -> MARKETING & GROWTH | B27: =Settings!$C$6 -> USD | D27: ='SG&A'!F23 -> 0 | E27: ='SG&A'!G23 -> 0 | F27: ='SG&A'!H23 -> 3000 | G27: ='SG&A'!I23 -> 3000 | H27: ='SG&A'!J23 -> 3000 | I27: ='SG&A'!K23 -> 3000 | J27: ='SG&A'!L23 -> 3000 | K27: ='SG&A'!M23 -> 3000 | ... DG27: ='SG&A'!DI23 -> 40000
A28: ='SG&A'!A24 -> LEGAL, ADVISORY, PROF. SERVICES | B28: =Settings!$C$6 -> USD | D28: ='SG&A'!F24 -> 0 | E28: ='SG&A'!G24 -> 0 | F28: ='SG&A'!H24 -> 0 | G28: ='SG&A'!I24 -> 1500 | H28: ='SG&A'!J24 -> 1500 | I28: ='SG&A'!K24 -> 1500 | J28: ='SG&A'!L24 -> 1500 | K28: ='SG&A'!M24 -> 1500 | ... DG28: ='SG&A'!DI24 -> 7000
A29: ='SG&A'!A25 -> WFA Stipend | B29: =Settings!$C$6 -> USD | D29: ='SG&A'!F25 -> 9000 | E29: ='SG&A'!G25 -> 0 | F29: ='SG&A'!H25 -> 0 | G29: ='SG&A'!I25 -> 6000 | H29: ='SG&A'!J25 -> 0 | I29: ='SG&A'!K25 -> 0 | J29: ='SG&A'!L25 -> 3000 | K29: ='SG&A'!M25 -> 0 | ... DG29: ='SG&A'!DI25 -> 0
A30: ='SG&A'!A26 -> TECH SUPPORT & SERVICES | B30: =Settings!$C$6 -> USD | D30: ='SG&A'!F26 -> 0 | E30: ='SG&A'!G26 -> 0 | F30: ='SG&A'!H26 -> 0 | G30: ='SG&A'!I26 -> 0 | H30: ='SG&A'!J26 -> 0 | I30: ='SG&A'!K26 -> 221.25 | J30: ='SG&A'!L26 -> 250.5 | K30: ='SG&A'!M26 -> 250.5 | ... DG30: ='SG&A'!DI26 -> 1537.5
A31: ='SG&A'!A27 -> INSURANCE | B31: =Settings!$C$6 -> USD | D31: ='SG&A'!F27 -> 0 | E31: ='SG&A'!G27 -> 0 | F31: ='SG&A'!H27 -> 0 | G31: ='SG&A'!I27 -> 0 | H31: ='SG&A'!J27 -> 0 | I31: ='SG&A'!K27 -> 0 | J31: ='SG&A'!L27 -> 0 | K31: ='SG&A'!M27 -> 0 | ... DG31: ='SG&A'!DI27 -> 2000
A32: ='SG&A'!A28 -> 0 | B32: =Settings!$C$6 -> USD | D32: ='SG&A'!F28 -> 0 | E32: ='SG&A'!G28 -> 0 | F32: ='SG&A'!H28 -> 0 | G32: ='SG&A'!I28 -> 0 | H32: ='SG&A'!J28 -> 0 | I32: ='SG&A'!K28 -> 0 | J32: ='SG&A'!L28 -> 0 | K32: ='SG&A'!M28 -> 0 | ... DG32: ='SG&A'!DI28 -> 0
A33: ='SG&A'!A29 -> OTHER EXPENSES | B33: =Settings!$C$6 -> USD | D33: ='SG&A'!F29 -> 0 | E33: ='SG&A'!G29 -> 0 | F33: ='SG&A'!H29 -> 0 | G33: ='SG&A'!I29 -> 0 | H33: ='SG&A'!J29 -> 0 | I33: ='SG&A'!K29 -> 0 | J33: ='SG&A'!L29 -> 0 | K33: ='SG&A'!M29 -> 0 | ... DG33: ='SG&A'!DI29 -> 0
A34: EBITDA | B34: =Settings!$C$6 -> USD | D34: =D22-D25 -> -20458.333 | E34: =E22-E25 -> -6875 | F34: =F22-F25 -> -9875 | G34: =G22-G25 -> -21958.333 | H34: =H22-H25 -> -15958.333 | I34: =I22-I25 -> -16179.583 | J34: =J22-J25 -> -21500.5 | K34: =K22-K25 -> -18500.5 | ... DG34: =DG22-DG25 -> 3844231.5
A35: EBITDA margin | B35: % | D35: =IFERROR(MAX((D34/D$12),0),"-") -> - | E35: =IFERROR(MAX((E34/E$12),0),"-") -> - | F35: =IFERROR(MAX((F34/F$12),0),"-") -> - | G35: =IFERROR(MAX((G34/G$12),0),"-") -> - | H35: =IFERROR(MAX((H34/H$12),0),"-") -> - | I35: =IFERROR(MAX((I34/I$12),0),"-") -> - | J35: =IFERROR(MAX((J34/J$12),0),"-") -> - | K35: =IFERROR(MAX((K34/K$12),0),"-") -> - | ... DG35: =IFERROR(MAX((DG34/DG$12),0),"-") -> 0.65585381
A37: D&A | B37: =Settings!$C$6 -> USD | D37: ='WK+CAPEX'!D77 -> 0 | E37: ='WK+CAPEX'!E77 -> 0 | F37: ='WK+CAPEX'!F77 -> 0 | G37: ='WK+CAPEX'!G77 -> 0 | H37: ='WK+CAPEX'!H77 -> 0 | I37: ='WK+CAPEX'!I77 -> 0 | J37: ='WK+CAPEX'!J77 -> 0 | K37: ='WK+CAPEX'!K77 -> 0 | ... AH37: ='WK+CAPEX'!AH77 -> 0 | AI37: 0 | AJ37: 0 | AK37: 0 | AL37: 0 | AM37: 0 | AN37: 0 | AO37: 0 | AP37: 0 | AQ37: 0 | AR37: 0 | AS37: 0 | AT37: 0 | AU37: 0 | AV37: 0 | AW37: 0 | AX37: 0 | AY37: 0 | AZ37: 0 | BA37: 0 | BB37: 0 | BC37: 0 | BD37: 0 | BE37: 0 | BF37: 0 | BG37: 0 | BH37: 0 | BI37: 0 | BJ37: 0 | BK37: 0 | BL37: 0 | BM37: 0 | BN37: 0 | BO37: 0 | BP37: 0 | BQ37: 0 | BR37: 0 | BS37: 0 | BT37: 0 | BU37: 0 | BV37: 0 | BW37: 0 | BX37: 0 | BY37: 0 | BZ37: 0 | CA37: 0 | CB37: 0 | CC37: 0 | CD37: 0 | CE37: 0 | CF37: 0 | CG37: 0 | CH37: 0 | CI37: 0 | CJ37: 0 | CK37: 0 | CL37: 0 | CM37: 0 | CN37: 0 | CO37: 0 | CP37: 0 | CQ37: 0 | CR37: 0 | CS37: 0 | CT37: 0 | CU37: 0 | CV37: 0 | CW37: 0 | CX37: 0 | CY37: 0 | CZ37: 0 | DA37: 0 | DB37: 0 | DC37: 0 | DD37: 0 | DE37: 0 | DF37: 0 | DG37: 0
A38: EBIT | B38: =Settings!$C$6 -> USD | D38: =D34-D37 -> -20458.333 | E38: =E34-E37 -> -6875 | F38: =F34-F37 -> -9875 | G38: =G34-G37 -> -21958.333 | H38: =H34-H37 -> -15958.333 | I38: =I34-I37 -> -16179.583 | J38: =J34-J37 -> -21500.5 | K38: =K34-K37 -> -18500.5 | ... DG38: =DG34-DG37 -> 3844231.5
A39: EBIT margin | E39: =IFERROR(MAX((E38/E$12),0),"-") -> - | F39: =IFERROR(MAX((F38/F$12),0),"-") -> - | G39: =IFERROR(MAX((G38/G$12),0),"-") -> - | H39: =IFERROR(MAX((H38/H$12),0),"-") -> - | I39: =IFERROR(MAX((I38/I$12),0),"-") -> - | J39: =IFERROR(MAX((J38/J$12),0),"-") -> - | K39: =IFERROR(MAX((K38/K$12),0),"-") -> - | L39: =IFERROR(MAX((L38/L$12),0),"-") -> - | ... DG39: =IFERROR(MAX((DG38/DG$12),0),"-") -> 0.65585381
A41: Interest expense | B41: =Settings!$C$6 -> USD | D41: =D63*(Settings!$C$24/12) -> 0 | E41: =E63*(Settings!$C$24/12) -> 0 | F41: =F63*(Settings!$C$24/12) -> 0 | G41: =G63*(Settings!$C$24/12) -> 0 | H41: =H63*(Settings!$C$24/12) -> 0 | I41: =I63*(Settings!$C$24/12) -> 0 | J41: =J63*(Settings!$C$24/12) -> 0 | K41: =K63*(Settings!$C$24/12) -> 0 | ... DG41: =DG63*(Settings!$C$24/12) -> 0
A42: Income taxes | B42: =Settings!$C$6 -> USD | D42: =IF(D38>0,D38*Settings!$C$16,"0") -> 0 | E42: =IF(E38>0,E38*Settings!$C$16,"0") -> 0 | F42: =IF(F38>0,F38*Settings!$C$16,"0") -> 0 | G42: =IF(G38>0,G38*Settings!$C$16,"0") -> 0 | H42: =IF(H38>0,H38*Settings!$C$16,"0") -> 0 | I42: =IF(I38>0,I38*Settings!$C$16,"0") -> 0 | J42: =IF(J38>0,J38*Settings!$C$16,"0") -> 0 | K42: =IF(K38>0,K38*Settings!$C$16,"0") -> 0 | ... DG42: =IF(DG38>0,DG38*Settings!$C$16,"0") -> 0
